Workbook

Sheet Monthly Report
D1: General Manager Room Inspection Program
D3: Monthly Summary Report
D6: Cumulative Inspection Score Average | K6: Cumulative Percentages
A7: # Inspected | B7: Inspector | D7: Bedroom | F7: Bathroom | G7: Combined Cleanliness | H7: Maintenance | K7: Perfect | L7: OK | M7: N/A
A8: =+COUNTIF(D14:D29,B8) -> 0 | B8: Denise | D8: =SUMIF($D$14:$D$29,B8,$G$14:$G$29)/A8 -> #DIV/0! | F8: =SUMIF($D$14:$D$29,B8,$H$14:$H$29)/$A8 -> #DIV/0! | G8: =+D8+F8 -> #DIV/0! | H8: =SUMIF($D$14:$D$29,B8,$I$14:$I$29)/$A8 -> #DIV/0! | K8: =(SUMIF($D$14:$D$29,$B8,$K$14:$K$29))/$A8 -> #DIV/0! | L8: =(SUMIF($D$14:$D$29,$B8,$L$14:$L$29))/$A8 -> #DIV/0! | M8: =(SUMIF($D$14:$D$29,$B8,$M$14:$M$29))/$A8 -> #DIV/0!
A9: =+COUNTIF(D14:D29,B9) -> 7 | B9: Kelsey | D9: =SUMIF($D$14:$D$29,B9,$G$14:$G$29)/A9 -> 0.28571429 | F9: =SUMIF($D$14:$D$29,B9,$H$14:$H$29)/A9 -> 0.14285714 | G9: =+D9+F9 -> 0.42857143 | H9: =SUMIF($D$14:$D$29,B9,$I$14:$I$29)/$A9 -> 0 | K9: =(SUMIF($D$14:$D$29,$B9,$K$14:$K$29))/$A9 -> 0.99428571 | L9: =(SUMIF($D$14:$D$29,$B9,$L$14:$L$29))/$A9 -> 0.0057142857 | M9: =(SUMIF($D$14:$D$29,$B9,$M$14:$M$29))/$A9 -> 0
A10: =+COUNTIF(D14:D29,B10) -> 0 | B10: Kim | D10: =SUMIF($D$14:$D$29,B10,$G$14:$G$29)/A10 -> #DIV/0! | F10: =SUMIF($D$14:$D$29,B10,$H$14:$H$29)/A10 -> #DIV/0! | G10: =+D10+F10 -> #DIV/0! | H10: =SUMIF($D$14:$D$29,B10,$I$14:$I$29)/$A10 -> #DIV/0! | K10: =(SUMIF($D$14:$D$29,$B10,$K$14:$K$29))/$A10 -> #DIV/0! | L10: =(SUMIF($D$14:$D$29,$B10,$L$14:$L$29))/$A10 -> #DIV/0! | M10: =(SUMIF($D$14:$D$29,$B10,$M$14:$M$29))/$A10 -> #DIV/0!
D12: Insepction Scores | K12: Housekeeping Percentages
B13: Date Inspected | D13: Inspector | F13: Room # | G13: Bedroom | H13: Bathroom | I13: Maintenance | K13: Perfect | L13: OK | M13: N/A
A14: Room 1 | B14: {=+'Room 1'!B3:C3} -> 46163 | C14: 0 | D14: =+'Room 1'!C5 -> Kelsey | F14: =+'Room 1'!H3 -> 217 | G14: =+'Room 1'!C60+'Room 1'!D60 -> 0 | H14: =+'Room 1'!C90+'Room 1'!D90 -> 0 | I14: =+'Room 1'!C113+'Room 1'!D113 -> 0 | K14: =+'Room 1'!L3 -> 1 | L14: =+'Room 1'!M3 -> 0 | M14: =+'Room 1'!N3 -> 0
A15: Room 2 | B15: {=+'Room 2'!B3:C3} -> 46163 | C15: 0 | D15: =+'Room 2'!C5 -> Kelsey | F15: =+'Room 2'!H3 -> 313 | G15: =+'Room 2'!C60+'Room 2'!D60 -> 0 | H15: =+'Room 2'!C90+'Room 2'!D90 -> 0 | I15: =+'Room 2'!C113+'Room 2'!D113 -> 0 | K15: =+'Room 2'!L3 -> 1 | L15: =+'Room 2'!M3 -> 0 | M15: =+'Room 1'!N3 -> 0
A16: Room 3 | B16: {=+'Room 3'!B3:C3} -> 46163 | C16: 0 | D16: =+'Room 3'!C5 -> Kelsey | F16: =+'Room 3'!H3 -> 103 | G16: =+'Room 3'!C60+'Room 3'!D60 -> 0 | H16: =+'Room 3'!C90+'Room 3'!D90 -> 1 | I16: =+'Room 3'!C113+'Room 3'!D113 -> 0 | K16: =+'Room 3'!L3 -> 0.98666667 | L16: =+'Room 3'!M3 -> 0.013333333 | M16: =+'Room 3'!N3 -> 0
A17: Room 4 | B17: {=+'Room 4'!B3:C3} -> 46163 | C17: 0 | D17: =+'Room 4'!C5 -> Kelsey | F17: =+'Room 4'!H3 -> 408 | G17: =+'Room 4'!C60+'Room 4'!D60 -> 0 | H17: =+'Room 4'!C90+'Room 4'!D90 -> 0 | I17: =+'Room 4'!C113+'Room 4'!D113 -> 0 | K17: =+'Room 4'!L3 -> 1 | L17: =+'Room 4'!M3 -> 0 | M17: =+'Room 4'!N3 -> 0
A18: Room 5 | B18: {=+'Room 5'!B3:C3} -> 46163 | C18: 0 | D18: =+'Room 5'!C5 -> Kelsey | F18: =+'Room 5'!H3 -> 212 | G18: =+'Room 5'!C60+'Room 5'!D60 -> 1 | H18: =+'Room 5'!C90+'Room 5'!D90 -> 0 | I18: =+'Room 5'!C113+'Room 5'!D113 -> 0 | K18: =+'Room 5'!L3 -> 0.98666667 | L18: =+'Room 5'!M3 -> 0.013333333 | M18: =+'Room 5'!N3 -> 0
A19: Room 6 | B19: {=+'Room 6'!B3:C3} -> 46168 | C19: 0 | D19: =+'Room 6'!C5 -> Kelsey | F19: =+'Room 6'!H3 -> 313 | G19: =+'Room 6'!C60+'Room 6'!D60 -> 0 | H19: =+'Room 6'!C90+'Room 6'!D90 -> 0 | I19: =+'Room 6'!C113+'Room 6'!D113 -> 0 | K19: =+'Room 6'!L3 -> 1 | L19: =+'Room 6'!M3 -> 0 | M19: =+'Room 6'!N3 -> 0
A20: Room 7 | B20: {=+'Room 7'!B3:C3} -> 46168 | C20: 0 | D20: =+'Room 7'!C5 -> 0 | F20: =+'Room 7'!H3 -> 315 | G20: =+'Room 7'!C60+'Room 7'!D60 -> 1 | H20: =+'Room 7'!C90+'Room 7'!D90 -> 0 | I20: =+'Room 7'!C113+'Room 7'!D113 -> 0 | K20: =+'Room 7'!L3 -> 0.98666667 | L20: =+'Room 7'!M3 -> 0.013333333 | M20: =+'Room 7'!N3 -> 0
A21: Room 8 | B21: {=+'Room 8'!B3:C3} -> 46168 | C21: 0 | D21: =+'Room 8'!C5 -> Kelsey | F21: =+'Room 8'!H3 -> 200 | G21: =+'Room 8'!C60+'Room 8'!D60 -> 1 | H21: =+'Room 8'!C90+'Room 8'!D90 -> 0 | I21: =+'Room 8'!C113+'Room 8'!D113 -> 0 | K21: =+'Room 8'!L3 -> 0.98666667 | L21: =+'Room 8'!M3 -> 0.013333333 | M21: =+'Room 8'!N3 -> 0
A22: Room 9 | B22: {=+'Room 9'!B3:C3} -> 0 | C22: 0 | D22: =+'Room 9'!C5 -> 0 | F22: =+'Room 9'!H3 -> 0 | G22: =+'Room 9'!C60+'Room 9'!D60 -> 0 | H22: =+'Room 9'!C90+'Room 9'!D90 -> 0 | I22: =+'Room 9'!C113+'Room 9'!D113 -> 0 | K22: =+'Room 9'!L3 -> 1 | L22: =+'Room 9'!M3 -> 0 | M22: =+'Room 9'!N3 -> 0
A23: Room 10 | B23: {=+'Room 10'!B3:C3} -> 0 | C23: 0 | D23: =+'Room 10'!C5 -> 0 | F23: =+'Room 10'!H3 -> 0 | G23: =+'Room 10'!C60+'Room 10'!D60 -> 0 | H23: =+'Room 10'!C90+'Room 10'!D90 -> 0 | I23: =+'Room 10'!C113+'Room 10'!D113 -> 0 | K23: =+'Room 10'!L3 -> 1 | L23: =+'Room 10'!M3 -> 0 | M23: =+'Room 10'!N3 -> 0
A24: Room 11 | B24: {=+'Room 11'!B3:C3} -> 0 | C24: 0 | D24: =+'Room 11'!C5 -> 0 | F24: =+'Room 11'!H3 -> 0 | G24: =+'Room 11'!C60+'Room 11'!D60 -> 0 | H24: =+'Room 11'!C90+'Room 11'!D90 -> 0 | I24: =+'Room 11'!C113+'Room 11'!D113 -> 0 | K24: =+'Room 11'!L3 -> 1 | L24: =+'Room 11'!M3 -> 0 | M24: =+'Room 11'!N3 -> 0
A25: Room 12 | B25: {=+'Room 12'!B3:C3} -> 0 | C25: 0 | D25: =+'Room 12'!C5 -> 0 | F25: =+'Room 12'!H3 -> 0 | G25: =+'Room 12'!C60+'Room 12'!D60 -> 0 | H25: =+'Room 12'!C90+'Room 12'!D90 -> 0 | I25: =+'Room 12'!C113+'Room 12'!D113 -> 0 | K25: =+'Room 12'!L3 -> 1 | L25: =+'Room 12'!M3 -> 0 | M25: =+'Room 12'!N3 -> 0
A26: Room 13 | B26: {=+'Room 13'!B3:C3} -> 0 | C26: 0 | D26: =+'Room 13'!C5 -> 0 | F26: =+'Room 13'!H3 -> 0 | G26: =+'Room 13'!C60+'Room 13'!D60 -> 0 | H26: =+'Room 13'!C90+'Room 13'!D90 -> 0 | I26: =+'Room 13'!C113+'Room 13'!D113 -> 0 | K26: =+'Room 13'!L3 -> 1 | L26: =+'Room 13'!M3 -> 0 | M26: =+'Room 13'!N3 -> 0
A27: Room 14 | B27: {=+'Room 14'!B3:C3} -> 0 | C27: 0 | D27: =+'Room 14'!C5 -> 0 | F27: =+'Room 14'!H3 -> 0 | G27: =+'Room 14'!C60+'Room 14'!D60 -> 0 | H27: =+'Room 14'!C90+'Room 14'!D90 -> 0 | I27: =+'Room 14'!C113+'Room 14'!D113 -> 0 | K27: =+'Room 13'!L3 -> 1 | L27: =+'Room 13'!M3 -> 0 | M27: =+'Room 13'!N3 -> 0
A28: Room 15 | B28: {=+'Room 15'!B3:C3} -> 0 | C28: 0 | D28: =+'Room 15'!C5 -> 0 | F28: =+'Room 15'!H3 -> 0 | G28: =+'Room 15'!C60+'Room 15'!D60 -> 0 | H28: =+'Room 15'!C90+'Room 15'!D90 -> 0 | I28: =+'Room 15'!C113+'Room 15'!D113 -> 0 | K28: =+'Room 15'!L3 -> 1 | L28: =+'Room 15'!M3 -> 0 | M28: =+'Room 15'!N3 -> 0
A29: Room 16 | B29: {=+'Room 16'!B3:C3} -> 0 | C29: 0 | D29: =+'Room 16'!C5 -> 0 | F29: =+'Room 16'!H3 -> 0 | G29: =+'Room 16'!C60+'Room 16'!D60 -> 0 | H29: =+'Room 16'!C90+'Room 16'!D90 -> 0 | I29: =+'Room 16'!C113+'Room 16'!D113 -> 0 | K29: =+'Room 16'!L3 -> 1 | L29: =+'Room 16'!M3 -> 0 | M29: =+'Room 16'!N3 -> 0
A31: 1) | B31: Complete 4 scored inspections / week. | G31: 2) | H31: Randomly select VC rooms from the VC Room list
A32: 3) | B32: Document three rooms per week which were inspected by your Hskpg Mgr / Sup. and 1 from the secondary inspector. GM's may have Hkpg Mgr perform additional scored inspections on rooms inspected by the fill in inspectress but those would not be considered as part of the EOM submittal.
A35: 4) | B35: The names of the inspectresses should be input in the green cells on the Monthly Report tab
A36: 5) | B36: The "looking for" descriptions may be edited on the Room 1 tab and all edits will flow through to the other tabs.
A37: 6) | B37: The default value for each line is "Perfect" - once you enter an X into one of the other two columns, the X in the perfect
B38: column will go away so that you don't have to enter X's into lines for items which you didn't find a deficiency.

Sheet Room 1
C1: General Manager Room Inspection
K2: Score | L2: % Perfect | M2: % OK | N2: % N/A
A3: Date | B3: 46163 | F3: Room Number | H3: 217 | J3: Housekeeping Score | K3: =+C60+D60+C90+D90 -> 0 | L3: =+(B60+B90)/75 -> 1 | M3: =+(C60+C90)/75 -> 0 | N3: =1-(L3+M3) -> 0
A5: Room Last Inspected by: | C5: Kelsey | H5: pw = enterinfo | J5: Maintenance Score | K5: =C113+D113 -> 0 | L5: =+B113/19 -> 1 | M5: =+C113/17 -> 0 | N5: =1-(L5+M5) -> 0
A6: Bedroom
B8: Perfect | C8: OK | D8: N/A | F8: Notes | J8: Looking for
A9: Entry Door | B9: =+IF(OR(C9="x",D9="x"),0,"x") -> x | J9: Clean & free of scuffs
A10: Entry Light | B10: =+IF(OR(C10="x",D10="x"),0,"x") -> x | J10: Bulbs working, no bugs or debris
A11: Mirror | B11: =+IF(OR(C11="x",D11="x"),0,"x") -> x | J11: No streaks, no dust
A12: Trash Can | B12: =+IF(OR(C12="x",D12="x"),0,"x") -> x | J12: Clean & bag tied
A13: Behind trash can (Wall) | B13: =+IF(OR(C13="x",D13="x"),0,"x") -> x | J13: No soil spots on wall or furniture piece behind trash can
A14: Desk | B14: =+IF(OR(C14="x",D14="x"),0,"x") -> x | J14: Clean surface & no fingerprints
A15: Desk Chair | B15: =+IF(OR(C15="x",D15="x"),0,"x") -> x | J15: Seat / back clean, no dust on base
A16: TV / Media Board | B16: =+IF(OR(C16="x",D16="x"),0,"x") -> x | J16: No soiled spots
A17: Literature / Signage | B17: =+IF(OR(C17="x",D17="x"),0,"x") -> x | J17: Sat. & Hskpg card, Channel Guide & other - present & in perfect condition
A18: Coffee Tray / Brewer | B18: =+IF(OR(C18="x",D18="x"),0,"x") -> x | J18: Brewer clean inside & no debris or soiled spots on or below tray
A19: Ice Bucket | B19: =+IF(OR(C19="x",D19="x"),0,"x") -> x | J19: Clean inside and out with liner
A20: Coffee Amenities | B20: =+IF(OR(C20="x",D20="x"),0,"x") -> x | J20: Proper quantity of items & presented properly
... A46: Pillow cases | B46: =+IF(OR(C46="x",D46="x"),0,"x") -> x | J46: Not wrinkled, properly tuckeed & top corners pointed
A47: General Manager Room Inspection (Bedroom continued)
B48: Perfect | C48: OK | D48: N/A | F48: Notes | J48: Looking for
A49: Top Sheet | B49: =+IF(OR(C49="x",D49="x"),0,"x") -> x | J49: Pulled tight, not or minimally wrinkled, no stains
A50: Artwork 2 | B50: =+IF(OR(C50="x",D50="x"),0,"x") -> x | J50: No dust
A51: Nightstand 2 (if K) | B51: =+IF(OR(C51="x",D51="x"),0,"x") -> x | J51: Clean top surface, both sides, drawer and wall behind nightstand
A52: Sofa / Chair | B52: =+IF(OR(C52="x",D52="x"),0,"x") -> x | J52: No soiled cushions, zipper to back
A53: Sofa Sleeper | B53: =+IF(OR(C53="x",D53="x"),0,"x") -> x | J53: No dirty linen, mattress clean no debris underneath
A54: Coffee / End Table | B54: =+IF(OR(C54="x",D54="x"),0,"x") -> x | J54: Clean surface, no dust or soil on legs
A55: Wall | B55: =+IF(OR(C55="x",D55="x"),0,"x") -> x | J55: Not scuffed or soiled
A56: Closet (stocked) | B56: =+IF(OR(C56="x",D56="x"),0,"x") -> x | J56: Proper number of matching hangers, laundry bag
A57: Iron / Ironing Board | B57: =+IF(OR(C57="x",D57="x"),0,"x") -> x | J57: no water in iron, cord neatly wrapped, board cover not stained / soiled
A58: Closet Door | B58: =+IF(OR(C58="x",D58="x"),0,"x") -> x | J58: Clean
A59: Floor | B59: =+IF(OR(C59="x",D59="x"),0,"x") -> x | J59: Carpet thoroughly vacuumed & free of debris & soiling - incl. corners / edges
A60: Bedroom Total | B60: =COUNTIF(B9:B59,"x") -> 49 | C60: =COUNTIF(C9:C59,"x") -> 0 | D60: =(COUNTIF(D9:D59,"x")*2)+(COUNTIF(D59,"x")+COUNTIF(D49,"x")+COUNTIF(D46,"x")+COUNTIF(D43,"x")+COUNTIF(D33,"x")+COUNTIF(D32,"x")+COUNTIF(D29,"x"))*2 -> 0 | F60: Perfect = 0 points, OK = 1 point, Not Acceptable (NA) = 2 points, Red boxes = 4 points
A62: Bathroom
B63: Perfect | C63: OK | D63: N/A | F63: Notes | J63: Looking for
A64: Hair Dryer | B64: =+IF(OR(C64="x",D64="x"),0,"x") -> x | J64: Clean & no lint or hair in filter screen
A65: Lotion Dispenser | B65: =+IF(OR(C65="x",D65="x"),0,"x") -> x | J65: Clean and adequately filled
A66: Mirror | B66: =+IF(OR(C66="x",D66="x"),0,"x") -> x | J66: No dust around edges, no spots or smudges on mirror
A67: Amenities | B67: =+IF(OR(C67="x",D67="x"),0,"x") -> x | J67: Properly stocked and presented
A68: Amenity Tray | B68: =+IF(OR(C68="x",D68="x"),0,"x") -> x | J68: Clean - top and on vanity underneath
...

Sheet Room 2
C1: General Manager Room Inspection
K2: Score | L2: % Perfect | M2: % OK | N2: % N/A
A3: Date | B3: 46163 | F3: Room Number | H3: 313 | J3: Housekeeping Score | K3: =+C60+D60+C90+D90 -> 0 | L3: =+(B60+B90)/75 -> 1 | M3: =+(C60+C90)/75 -> 0 | N3: =1-(L3+M3) -> 0
A5: Room Last Inspected by: | C5: Kelsey | H5: pw = enterinfo | J5: Maintenance Score | K5: =C113+D113 -> 0 | L5: =+B113/19 -> 1 | M5: =+C113/17 -> 0 | N5: =1-(L5+M5) -> 0
A6: Bedroom
B8: Perfect | C8: OK | D8: N/A | F8: Notes | J8: Looking for
A9: Entry Door | B9: =+IF(OR(C9="x",D9="x"),0,"x") -> x | J9: =+'Room 1'!J9 -> Clean & free of scuffs
A10: Entry Light | B10: =+IF(OR(C10="x",D10="x"),0,"x") -> x | J10: =+'Room 1'!J10 -> Bulbs working, no bugs or debris
A11: Mirror | B11: =+IF(OR(C11="x",D11="x"),0,"x") -> x | J11: =+'Room 1'!J11 -> No streaks, no dust
A12: Trash Can | B12: =+IF(OR(C12="x",D12="x"),0,"x") -> x | J12: =+'Room 1'!J12 -> Clean & bag tied
A13: Behind trash can (Wall) | B13: =+IF(OR(C13="x",D13="x"),0,"x") -> x | J13: =+'Room 1'!J13 -> No soil spots on wall or furniture piece behind trash can
A14: Desk | B14: =+IF(OR(C14="x",D14="x"),0,"x") -> x | J14: =+'Room 1'!J14 -> Clean surface & no fingerprints
A15: Desk Chair | B15: =+IF(OR(C15="x",D15="x"),0,"x") -> x | J15: =+'Room 1'!J15 -> Seat / back clean, no dust on base
A16: TV / Media Board | B16: =+IF(OR(C16="x",D16="x"),0,"x") -> x | J16: =+'Room 1'!J16 -> No soiled spots
A17: Literature / Signage | B17: =+IF(OR(C17="x",D17="x"),0,"x") -> x | J17: =+'Room 1'!J17 -> Sat. & Hskpg card, Channel Guide & other - present & in perfect condition
A18: Coffee Tray / Brewer | B18: =+IF(OR(C18="x",D18="x"),0,"x") -> x | J18: =+'Room 1'!J18 -> Brewer clean inside & no debris or soiled spots on or below tray
A19: Ice Bucket | B19: =+IF(OR(C19="x",D19="x"),0,"x") -> x | J19: =+'Room 1'!J19 -> Clean inside and out with liner
A20: Coffee Amenities | B20: =+IF(OR(C20="x",D20="x"),0,"x") -> x | J20: =+'Room 1'!J20 -> Proper quantity of items & presented properly
... A46: Pillow cases | B46: =+IF(OR(C46="x",D46="x"),0,"x") -> x | J46: =+'Room 1'!J46 -> Not wrinkled, properly tuckeed & top corners pointed
A47: General Manager Room Inspection (Bedroom continued)
B48: Perfect | C48: OK | D48: N/A | F48: Notes | J48: Looking for
A49: Top Sheet | B49: =+IF(OR(C49="x",D49="x"),0,"x") -> x | J49: =+'Room 1'!J49 -> Pulled tight, not or minimally wrinkled, no stains
A50: Artwork 2 | B50: =+IF(OR(C50="x",D50="x"),0,"x") -> x | J50: =+'Room 1'!J50 -> No dust
A51: Nightstand 2 (if K) | B51: =+IF(OR(C51="x",D51="x"),0,"x") -> x | J51: =+'Room 1'!J51 -> Clean top surface, both sides, drawer and wall behind nightstand
A52: Sofa / Chair | B52: =+IF(OR(C52="x",D52="x"),0,"x") -> x | J52: =+'Room 1'!J52 -> No soiled cushions, zipper to back
A53: Sofa Sleeper | B53: =+IF(OR(C53="x",D53="x"),0,"x") -> x | J53: =+'Room 1'!J53 -> No dirty linen, mattress clean no debris underneath
A54: Coffee / End Table | B54: =+IF(OR(C54="x",D54="x"),0,"x") -> x | J54: =+'Room 1'!J54 -> Clean surface, no dust or soil on legs
A55: Wall | B55: =+IF(OR(C55="x",D55="x"),0,"x") -> x | J55: =+'Room 1'!J55 -> Not scuffed or soiled
A56: Closet (stocked) | B56: =+IF(OR(C56="x",D56="x"),0,"x") -> x | J56: =+'Room 1'!J56 -> Proper number of matching hangers, laundry bag
A57: Iron / Ironing Board | B57: =+IF(OR(C57="x",D57="x"),0,"x") -> x | J57: =+'Room 1'!J57 -> no water in iron, cord neatly wrapped, board cover not stained / soiled
A58: Closet Door | B58: =+IF(OR(C58="x",D58="x"),0,"x") -> x | J58: =+'Room 1'!J58 -> Clean
A59: Floor | B59: =+IF(OR(C59="x",D59="x"),0,"x") -> x | J59: =+'Room 1'!J59 -> Carpet thoroughly vacuumed & free of debris & soiling - incl. corners / edges
A60: Bedroom Total | B60: =COUNTIF(B9:B59,"x") -> 49 | C60: =COUNTIF(C9:C59,"x") -> 0 | D60: =(COUNTIF(D9:D59,"x")*2)+(COUNTIF(D59,"x")+COUNTIF(D49,"x")+COUNTIF(D46,"x")+COUNTIF(D43,"x")+COUNTIF(D33,"x")+COUNTIF(D32,"x")+COUNTIF(D29,"x"))*2 -> 0 | F60: Perfect = 0 points, OK = 1 point, Not Acceptable (NA) = 2 points, Red boxes = 4 points
A62: Bathroom
B63: Perfect | C63: OK | D63: N/A | F63: Notes | J63: Looking for
A64: Hair Dryer | B64: =+IF(OR(C64="x",D64="x"),0,"x") -> x | J64: =+'Room 1'!J64 -> Clean & no lint or hair in filter screen
A65: Lotion Dispenser | B65: =+IF(OR(C65="x",D65="x"),0,"x") -> x | J65: =+'Room 1'!J65 -> Clean and adequately filled
A66: Mirror | B66: =+IF(OR(C66="x",D66="x"),0,"x") -> x | J66: =+'Room 1'!J66 -> No dust around edges, no spots or smudges on mirror
A67: Amenities | B67: =+IF(OR(C67="x",D67="x"),0,"x") -> x | J67: =+'Room 1'!J67 -> Properly stocked and presented
A68: Amenity Tray | B68: =+IF(OR(C68="x",D68="x"),0,"x") -> x | J68: =+'Room 1'!J68 -> Clean - top and on vanity underneath
...

Sheet Room 3
C1: General Manager Room Inspection
K2: Score | L2: % Perfect | M2: % OK | N2: % N/A
A3: Date | B3: 46163 | F3: Room Number | H3: 103 | J3: Housekeeping Score | K3: =+C60+D60+C90+D90 -> 1 | L3: =+(B60+B90)/75 -> 0.98666667 | M3: =+(C60+C90)/75 -> 0.013333333 | N3: =1-(L3+M3) -> 0
A5: Room Last Inspected by: | C5: Kelsey | H5: pw = enterinfo | J5: Maintenance Score | K5: =C113+D113 -> 0 | L5: =+B113/19 -> 1 | M5: =+C113/17 -> 0 | N5: =1-(L5+M5) -> 0
A6: Bedroom
B8: Perfect | C8: OK | D8: N/A | F8: Notes | J8: Looking for
A9: Entry Door | B9: =+IF(OR(C9="x",D9="x"),0,"x") -> x | J9: =+'Room 1'!J9 -> Clean & free of scuffs
A10: Entry Light | B10: =+IF(OR(C10="x",D10="x"),0,"x") -> x | J10: =+'Room 1'!J10 -> Bulbs working, no bugs or debris
A11: Mirror | B11: =+IF(OR(C11="x",D11="x"),0,"x") -> x | J11: =+'Room 1'!J11 -> No streaks, no dust
A12: Trash Can | B12: =+IF(OR(C12="x",D12="x"),0,"x") -> x | J12: =+'Room 1'!J12 -> Clean & bag tied
A13: Behind trash can (Wall) | B13: =+IF(OR(C13="x",D13="x"),0,"x") -> x | J13: =+'Room 1'!J13 -> No soil spots on wall or furniture piece behind trash can
A14: Desk | B14: =+IF(OR(C14="x",D14="x"),0,"x") -> x | J14: =+'Room 1'!J14 -> Clean surface & no fingerprints
A15: Desk Chair | B15: =+IF(OR(C15="x",D15="x"),0,"x") -> x | J15: =+'Room 1'!J15 -> Seat / back clean, no dust on base
A16: TV / Media Board | B16: =+IF(OR(C16="x",D16="x"),0,"x") -> x | J16: =+'Room 1'!J16 -> No soiled spots
A17: Literature / Signage | B17: =+IF(OR(C17="x",D17="x"),0,"x") -> x | J17: =+'Room 1'!J17 -> Sat. & Hskpg card, Channel Guide & other - present & in perfect condition
A18: Coffee Tray / Brewer | B18: =+IF(OR(C18="x",D18="x"),0,"x") -> x | J18: =+'Room 1'!J18 -> Brewer clean inside & no debris or soiled spots on or below tray
A19: Ice Bucket | B19: =+IF(OR(C19="x",D19="x"),0,"x") -> x | J19: =+'Room 1'!J19 -> Clean inside and out with liner
A20: Coffee Amenities | B20: =+IF(OR(C20="x",D20="x"),0,"x") -> x | J20: =+'Room 1'!J20 -> Proper quantity of items & presented properly
... A46: Pillow cases | B46: =+IF(OR(C46="x",D46="x"),0,"x") -> x | J46: =+'Room 1'!J46 -> Not wrinkled, properly tuckeed & top corners pointed
A47: General Manager Room Inspection (Bedroom continued)
B48: Perfect | C48: OK | D48: N/A | F48: Notes | J48: Looking for
A49: Top Sheet | B49: =+IF(OR(C49="x",D49="x"),0,"x") -> x | J49: =+'Room 1'!J49 -> Pulled tight, not or minimally wrinkled, no stains
A50: Artwork 2 | B50: =+IF(OR(C50="x",D50="x"),0,"x") -> x | J50: =+'Room 1'!J50 -> No dust
A51: Nightstand 2 (if K) | B51: =+IF(OR(C51="x",D51="x"),0,"x") -> x | J51: =+'Room 1'!J51 -> Clean top surface, both sides, drawer and wall behind nightstand
A52: Sofa / Chair | B52: =+IF(OR(C52="x",D52="x"),0,"x") -> x | J52: =+'Room 1'!J52 -> No soiled cushions, zipper to back
A53: Sofa Sleeper | B53: =+IF(OR(C53="x",D53="x"),0,"x") -> x | J53: =+'Room 1'!J53 -> No dirty linen, mattress clean no debris underneath
A54: Coffee / End Table | B54: =+IF(OR(C54="x",D54="x"),0,"x") -> x | J54: =+'Room 1'!J54 -> Clean surface, no dust or soil on legs
A55: Wall | B55: =+IF(OR(C55="x",D55="x"),0,"x") -> x | J55: =+'Room 1'!J55 -> Not scuffed or soiled
A56: Closet (stocked) | B56: =+IF(OR(C56="x",D56="x"),0,"x") -> x | J56: =+'Room 1'!J56 -> Proper number of matching hangers, laundry bag
A57: Iron / Ironing Board | B57: =+IF(OR(C57="x",D57="x"),0,"x") -> x | J57: =+'Room 1'!J57 -> no water in iron, cord neatly wrapped, board cover not stained / soiled
A58: Closet Door | B58: =+IF(OR(C58="x",D58="x"),0,"x") -> x | J58: =+'Room 1'!J58 -> Clean
A59: Floor | B59: =+IF(OR(C59="x",D59="x"),0,"x") -> x | J59: =+'Room 1'!J59 -> Carpet thoroughly vacuumed & free of debris & soiling - incl. corners / edges
A60: Bedroom Total | B60: =COUNTIF(B9:B59,"x") -> 49 | C60: =COUNTIF(C9:C59,"x") -> 0 | D60: =(COUNTIF(D9:D59,"x")*2)+(COUNTIF(D59,"x")+COUNTIF(D49,"x")+COUNTIF(D46,"x")+COUNTIF(D43,"x")+COUNTIF(D33,"x")+COUNTIF(D32,"x")+COUNTIF(D29,"x"))*2 -> 0 | F60: Perfect = 0 points, OK = 1 point, Not Acceptable (NA) = 2 points, Red boxes = 4 points
A62: Bathroom
B63: Perfect | C63: OK | D63: N/A | F63: Notes | J63: Looking for
A64: Hair Dryer | B64: =+IF(OR(C64="x",D64="x"),0,"x") -> x | J64: =+'Room 1'!J64 -> Clean & no lint or hair in filter screen
A65: Lotion Dispenser | B65: =+IF(OR(C65="x",D65="x"),0,"x") -> x | J65: =+'Room 1'!J65 -> Clean and adequately filled
A66: Mirror | B66: =+IF(OR(C66="x",D66="x"),0,"x") -> x | J66: =+'Room 1'!J66 -> No dust around edges, no spots or smudges on mirror
A67: Amenities | B67: =+IF(OR(C67="x",D67="x"),0,"x") -> x | J67: =+'Room 1'!J67 -> Properly stocked and presented
A68: Amenity Tray | B68: =+IF(OR(C68="x",D68="x"),0,"x") -> x | J68: =+'Room 1'!J68 -> Clean - top and on vanity underneath
...

Sheet Room 4
C1: General Manager Room Inspection
K2: Score | L2: % Perfect | M2: % OK | N2: % N/A
A3: Date | B3: 46163 | F3: Room Number | H3: 408 | J3: Housekeeping Score | K3: =+C60+D60+C90+D90 -> 0 | L3: =+(B60+B90)/75 -> 1 | M3: =+(C60+C90)/75 -> 0 | N3: =1-(L3+M3) -> 0
A5: Room Last Inspected by: | C5: Kelsey | H5: pw = enterinfo | J5: Maintenance Score | K5: =C113+D113 -> 0 | L5: =+B113/19 -> 1 | M5: =+C113/17 -> 0 | N5: =1-(L5+M5) -> 0
A6: Bedroom
B8: Perfect | C8: OK | D8: N/A | F8: Notes | J8: Looking for
A9: Entry Door | B9: =+IF(OR(C9="x",D9="x"),0,"x") -> x | J9: =+'Room 1'!J9 -> Clean & free of scuffs
A10: Entry Light | B10: =+IF(OR(C10="x",D10="x"),0,"x") -> x | J10: =+'Room 1'!J10 -> Bulbs working, no bugs or debris
A11: Mirror | B11: =+IF(OR(C11="x",D11="x"),0,"x") -> x | J11: =+'Room 1'!J11 -> No streaks, no dust
A12: Trash Can | B12: =+IF(OR(C12="x",D12="x"),0,"x") -> x | J12: =+'Room 1'!J12 -> Clean & bag tied
A13: Behind trash can (Wall) | B13: =+IF(OR(C13="x",D13="x"),0,"x") -> x | J13: =+'Room 1'!J13 -> No soil spots on wall or furniture piece behind trash can
A14: Desk | B14: =+IF(OR(C14="x",D14="x"),0,"x") -> x | J14: =+'Room 1'!J14 -> Clean surface & no fingerprints
A15: Desk Chair | B15: =+IF(OR(C15="x",D15="x"),0,"x") -> x | J15: =+'Room 1'!J15 -> Seat / back clean, no dust on base
A16: TV / Media Board | B16: =+IF(OR(C16="x",D16="x"),0,"x") -> x | J16: =+'Room 1'!J16 -> No soiled spots
A17: Literature / Signage | B17: =+IF(OR(C17="x",D17="x"),0,"x") -> x | J17: =+'Room 1'!J17 -> Sat. & Hskpg card, Channel Guide & other - present & in perfect condition
A18: Coffee Tray / Brewer | B18: =+IF(OR(C18="x",D18="x"),0,"x") -> x | J18: =+'Room 1'!J18 -> Brewer clean inside & no debris or soiled spots on or below tray
A19: Ice Bucket | B19: =+IF(OR(C19="x",D19="x"),0,"x") -> x | J19: =+'Room 1'!J19 -> Clean inside and out with liner
A20: Coffee Amenities | B20: =+IF(OR(C20="x",D20="x"),0,"x") -> x | J20: =+'Room 1'!J20 -> Proper quantity of items & presented properly
... A46: Pillow cases | B46: =+IF(OR(C46="x",D46="x"),0,"x") -> x | J46: =+'Room 1'!J46 -> Not wrinkled, properly tuckeed & top corners pointed
A47: General Manager Room Inspection (Bedroom continued)
B48: Perfect | C48: OK | D48: N/A | F48: Notes | J48: Looking for
A49: Top Sheet | B49: =+IF(OR(C49="x",D49="x"),0,"x") -> x | J49: =+'Room 1'!J49 -> Pulled tight, not or minimally wrinkled, no stains
A50: Artwork 2 | B50: =+IF(OR(C50="x",D50="x"),0,"x") -> x | J50: =+'Room 1'!J50 -> No dust
A51: Nightstand 2 (if K) | B51: =+IF(OR(C51="x",D51="x"),0,"x") -> x | J51: =+'Room 1'!J51 -> Clean top surface, both sides, drawer and wall behind nightstand
A52: Sofa / Chair | B52: =+IF(OR(C52="x",D52="x"),0,"x") -> x | J52: =+'Room 1'!J52 -> No soiled cushions, zipper to back
A53: Sofa Sleeper | B53: =+IF(OR(C53="x",D53="x"),0,"x") -> x | J53: =+'Room 1'!J53 -> No dirty linen, mattress clean no debris underneath
A54: Coffee / End Table | B54: =+IF(OR(C54="x",D54="x"),0,"x") -> x | J54: =+'Room 1'!J54 -> Clean surface, no dust or soil on legs
A55: Wall | B55: =+IF(OR(C55="x",D55="x"),0,"x") -> x | J55: =+'Room 1'!J55 -> Not scuffed or soiled
A56: Closet (stocked) | B56: =+IF(OR(C56="x",D56="x"),0,"x") -> x | J56: =+'Room 1'!J56 -> Proper number of matching hangers, laundry bag
A57: Iron / Ironing Board | B57: =+IF(OR(C57="x",D57="x"),0,"x") -> x | J57: =+'Room 1'!J57 -> no water in iron, cord neatly wrapped, board cover not stained / soiled
A58: Closet Door | B58: =+IF(OR(C58="x",D58="x"),0,"x") -> x | J58: =+'Room 1'!J58 -> Clean
A59: Floor | B59: =+IF(OR(C59="x",D59="x"),0,"x") -> x | J59: =+'Room 1'!J59 -> Carpet thoroughly vacuumed & free of debris & soiling - incl. corners / edges
A60: Bedroom Total | B60: =COUNTIF(B9:B59,"x") -> 49 | C60: =COUNTIF(C9:C59,"x") -> 0 | D60: =(COUNTIF(D9:D59,"x")*2)+(COUNTIF(D59,"x")+COUNTIF(D49,"x")+COUNTIF(D46,"x")+COUNTIF(D43,"x")+COUNTIF(D33,"x")+COUNTIF(D32,"x")+COUNTIF(D29,"x"))*2 -> 0 | F60: Perfect = 0 points, OK = 1 point, Not Acceptable (NA) = 2 points, Red boxes = 4 points
A62: Bathroom
B63: Perfect | C63: OK | D63: N/A | F63: Notes | J63: Looking for
A64: Hair Dryer | B64: =+IF(OR(C64="x",D64="x"),0,"x") -> x | J64: =+'Room 1'!J64 -> Clean & no lint or hair in filter screen
A65: Lotion Dispenser | B65: =+IF(OR(C65="x",D65="x"),0,"x") -> x | J65: =+'Room 1'!J65 -> Clean and adequately filled
A66: Mirror | B66: =+IF(OR(C66="x",D66="x"),0,"x") -> x | J66: =+'Room 1'!J66 -> No dust around edges, no spots or smudges on mirror
A67: Amenities | B67: =+IF(OR(C67="x",D67="x"),0,"x") -> x | J67: =+'Room 1'!J67 -> Properly stocked and presented
A68: Amenity Tray | B68: =+IF(OR(C68="x",D68="x"),0,"x") -> x | J68: =+'Room 1'!J68 -> Clean - top and on vanity underneath
...

Sheet Room 5
C1: General Manager Room Inspection
K2: Score | L2: % Perfect | M2: % OK | N2: % N/A
A3: Date | B3: 46163 | F3: Room Number | H3: 212 | J3: Housekeeping Score | K3: =+C60+D60+C90+D90 -> 1 | L3: =+(B60+B90)/75 -> 0.98666667 | M3: =+(C60+C90)/75 -> 0.013333333 | N3: =1-(L3+M3) -> 0
A5: Room Last Inspected by: | C5: Kelsey | H5: pw = enterinfo | J5: Maintenance Score | K5: =C113+D113 -> 0 | L5: =+B113/19 -> 1 | M5: =+C113/17 -> 0 | N5: =1-(L5+M5) -> 0
A6: Bedroom
B8: Perfect | C8: OK | D8: N/A | F8: Notes | J8: Looking for
A9: Entry Door | B9: =+IF(OR(C9="x",D9="x"),0,"x") -> 0 | C9: x | J9: =+'Room 1'!J9 -> Clean & free of scuffs
A10: Entry Light | B10: =+IF(OR(C10="x",D10="x"),0,"x") -> x | J10: =+'Room 1'!J10 -> Bulbs working, no bugs or debris
A11: Mirror | B11: =+IF(OR(C11="x",D11="x"),0,"x") -> x | J11: =+'Room 1'!J11 -> No streaks, no dust
A12: Trash Can | B12: =+IF(OR(C12="x",D12="x"),0,"x") -> x | J12: =+'Room 1'!J12 -> Clean & bag tied
A13: Behind trash can (Wall) | B13: =+IF(OR(C13="x",D13="x"),0,"x") -> x | J13: =+'Room 1'!J13 -> No soil spots on wall or furniture piece behind trash can
A14: Desk | B14: =+IF(OR(C14="x",D14="x"),0,"x") -> x | J14: =+'Room 1'!J14 -> Clean surface & no fingerprints
A15: Desk Chair | B15: =+IF(OR(C15="x",D15="x"),0,"x") -> x | J15: =+'Room 1'!J15 -> Seat / back clean, no dust on base
A16: TV / Media Board | B16: =+IF(OR(C16="x",D16="x"),0,"x") -> x | J16: =+'Room 1'!J16 -> No soiled spots
A17: Literature / Signage | B17: =+IF(OR(C17="x",D17="x"),0,"x") -> x | J17: =+'Room 1'!J17 -> Sat. & Hskpg card, Channel Guide & other - present & in perfect condition
A18: Coffee Tray / Brewer | B18: =+IF(OR(C18="x",D18="x"),0,"x") -> x | J18: =+'Room 1'!J18 -> Brewer clean inside & no debris or soiled spots on or below tray
A19: Ice Bucket | B19: =+IF(OR(C19="x",D19="x"),0,"x") -> x | J19: =+'Room 1'!J19 -> Clean inside and out with liner
A20: Coffee Amenities | B20: =+IF(OR(C20="x",D20="x"),0,"x") -> x | J20: =+'Room 1'!J20 -> Proper quantity of items & presented properly
A21: Microwave | B21: =+IF(OR(C21="x",D21="x"),0,"x") -> x | J21: =+'Room 1'!J21 -> Clean inside and out, no dust on top of microwave or around it in the cabinet.
... A46: Pillow cases | B46: =+IF(OR(C46="x",D46="x"),0,"x") -> x | J46: =+'Room 1'!J46 -> Not wrinkled, properly tuckeed & top corners pointed
A47: General Manager Room Inspection (Bedroom continued)
B48: Perfect | C48: OK | D48: N/A | F48: Notes | J48: Looking for
A49: Top Sheet | B49: =+IF(OR(C49="x",D49="x"),0,"x") -> x | J49: =+'Room 1'!J49 -> Pulled tight, not or minimally wrinkled, no stains
A50: Artwork 2 | B50: =+IF(OR(C50="x",D50="x"),0,"x") -> x | J50: =+'Room 1'!J50 -> No dust
A51: Nightstand 2 (if K) | B51: =+IF(OR(C51="x",D51="x"),0,"x") -> x | J51: =+'Room 1'!J51 -> Clean top surface, both sides, drawer and wall behind nightstand
A52: Sofa / Chair | B52: =+IF(OR(C52="x",D52="x"),0,"x") -> x | J52: =+'Room 1'!J52 -> No soiled cushions, zipper to back
A53: Sofa Sleeper | B53: =+IF(OR(C53="x",D53="x"),0,"x") -> x | J53: =+'Room 1'!J53 -> No dirty linen, mattress clean no debris underneath
A54: Coffee / End Table | B54: =+IF(OR(C54="x",D54="x"),0,"x") -> x | J54: =+'Room 1'!J54 -> Clean surface, no dust or soil on legs
A55: Wall | B55: =+IF(OR(C55="x",D55="x"),0,"x") -> x | J55: =+'Room 1'!J55 -> Not scuffed or soiled
A56: Closet (stocked) | B56: =+IF(OR(C56="x",D56="x"),0,"x") -> x | J56: =+'Room 1'!J56 -> Proper number of matching hangers, laundry bag
A57: Iron / Ironing Board | B57: =+IF(OR(C57="x",D57="x"),0,"x") -> x | J57: =+'Room 1'!J57 -> no water in iron, cord neatly wrapped, board cover not stained / soiled
A58: Closet Door | B58: =+IF(OR(C58="x",D58="x"),0,"x") -> x | J58: =+'Room 1'!J58 -> Clean
A59: Floor | B59: =+IF(OR(C59="x",D59="x"),0,"x") -> x | J59: =+'Room 1'!J59 -> Carpet thoroughly vacuumed & free of debris & soiling - incl. corners / edges
A60: Bedroom Total | B60: =COUNTIF(B9:B59,"x") -> 48 | C60: =COUNTIF(C9:C59,"x") -> 1 | D60: =(COUNTIF(D9:D59,"x")*2)+(COUNTIF(D59,"x")+COUNTIF(D49,"x")+COUNTIF(D46,"x")+COUNTIF(D43,"x")+COUNTIF(D33,"x")+COUNTIF(D32,"x")+COUNTIF(D29,"x"))*2 -> 0 | F60: Perfect = 0 points, OK = 1 point, Not Acceptable (NA) = 2 points, Red boxes = 4 points
A62: Bathroom
B63: Perfect | C63: OK | D63: N/A | F63: Notes | J63: Looking for
A64: Hair Dryer | B64: =+IF(OR(C64="x",D64="x"),0,"x") -> x | J64: =+'Room 1'!J64 -> Clean & no lint or hair in filter screen
A65: Lotion Dispenser | B65: =+IF(OR(C65="x",D65="x"),0,"x") -> x | J65: =+'Room 1'!J65 -> Clean and adequately filled
A66: Mirror | B66: =+IF(OR(C66="x",D66="x"),0,"x") -> x | J66: =+'Room 1'!J66 -> No dust around edges, no spots or smudges on mirror
A67: Amenities | B67: =+IF(OR(C67="x",D67="x"),0,"x") -> x | J67: =+'Room 1'!J67 -> Properly stocked and presented
...

Sheet Room 6
C1: General Manager Room Inspection
K2: Score | L2: % Perfect | M2: % OK | N2: % N/A
A3: Date | B3: 46168 | F3: Room Number | H3: 313 | J3: Housekeeping Score | K3: =+C60+D60+C90+D90 -> 0 | L3: =+(B60+B90)/75 -> 1 | M3: =+(C60+C90)/75 -> 0 | N3: =1-(L3+M3) -> 0
A5: Room Last Inspected by: | C5: Kelsey | H5: pw = enterinfo | J5: Maintenance Score | K5: =C113+D113 -> 0 | L5: =+B113/19 -> 1 | M5: =+C113/17 -> 0 | N5: =1-(L5+M5) -> 0
A6: Bedroom
B8: Perfect | C8: OK | D8: N/A | F8: Notes | J8: Looking for
A9: Entry Door | B9: =+IF(OR(C9="x",D9="x"),0,"x") -> x | J9: =+'Room 1'!J9 -> Clean & free of scuffs
A10: Entry Light | B10: =+IF(OR(C10="x",D10="x"),0,"x") -> x | J10: =+'Room 1'!J10 -> Bulbs working, no bugs or debris
A11: Mirror | B11: =+IF(OR(C11="x",D11="x"),0,"x") -> x | J11: =+'Room 1'!J11 -> No streaks, no dust
A12: Trash Can | B12: =+IF(OR(C12="x",D12="x"),0,"x") -> x | J12: =+'Room 1'!J12 -> Clean & bag tied
A13: Behind trash can (Wall) | B13: =+IF(OR(C13="x",D13="x"),0,"x") -> x | J13: =+'Room 1'!J13 -> No soil spots on wall or furniture piece behind trash can
A14: Desk | B14: =+IF(OR(C14="x",D14="x"),0,"x") -> x | J14: =+'Room 1'!J14 -> Clean surface & no fingerprints
A15: Desk Chair | B15: =+IF(OR(C15="x",D15="x"),0,"x") -> x | J15: =+'Room 1'!J15 -> Seat / back clean, no dust on base
A16: TV / Media Board | B16: =+IF(OR(C16="x",D16="x"),0,"x") -> x | J16: =+'Room 1'!J16 -> No soiled spots
A17: Literature / Signage | B17: =+IF(OR(C17="x",D17="x"),0,"x") -> x | J17: =+'Room 1'!J17 -> Sat. & Hskpg card, Channel Guide & other - present & in perfect condition
A18: Coffee Tray / Brewer | B18: =+IF(OR(C18="x",D18="x"),0,"x") -> x | J18: =+'Room 1'!J18 -> Brewer clean inside & no debris or soiled spots on or below tray
A19: Ice Bucket | B19: =+IF(OR(C19="x",D19="x"),0,"x") -> x | J19: =+'Room 1'!J19 -> Clean inside and out with liner
A20: Coffee Amenities | B20: =+IF(OR(C20="x",D20="x"),0,"x") -> x | J20: =+'Room 1'!J20 -> Proper quantity of items & presented properly
... A46: Pillow cases | B46: =+IF(OR(C46="x",D46="x"),0,"x") -> x | J46: =+'Room 1'!J46 -> Not wrinkled, properly tuckeed & top corners pointed
A47: General Manager Room Inspection (Bedroom continued)
B48: Perfect | C48: OK | D48: N/A | F48: Notes | J48: Looking for
A49: Top Sheet | B49: =+IF(OR(C49="x",D49="x"),0,"x") -> x | J49: =+'Room 1'!J49 -> Pulled tight, not or minimally wrinkled, no stains
A50: Artwork 2 | B50: =+IF(OR(C50="x",D50="x"),0,"x") -> x | J50: =+'Room 1'!J50 -> No dust
A51: Nightstand 2 (if K) | B51: =+IF(OR(C51="x",D51="x"),0,"x") -> x | J51: =+'Room 1'!J51 -> Clean top surface, both sides, drawer and wall behind nightstand
A52: Sofa / Chair | B52: =+IF(OR(C52="x",D52="x"),0,"x") -> x | J52: =+'Room 1'!J52 -> No soiled cushions, zipper to back
A53: Sofa Sleeper | B53: =+IF(OR(C53="x",D53="x"),0,"x") -> x | J53: =+'Room 1'!J53 -> No dirty linen, mattress clean no debris underneath
A54: Coffee / End Table | B54: =+IF(OR(C54="x",D54="x"),0,"x") -> x | J54: =+'Room 1'!J54 -> Clean surface, no dust or soil on legs
A55: Wall | B55: =+IF(OR(C55="x",D55="x"),0,"x") -> x | J55: =+'Room 1'!J55 -> Not scuffed or soiled
A56: Closet (stocked) | B56: =+IF(OR(C56="x",D56="x"),0,"x") -> x | J56: =+'Room 1'!J56 -> Proper number of matching hangers, laundry bag
A57: Iron / Ironing Board | B57: =+IF(OR(C57="x",D57="x"),0,"x") -> x | J57: =+'Room 1'!J57 -> no water in iron, cord neatly wrapped, board cover not stained / soiled
A58: Closet Door | B58: =+IF(OR(C58="x",D58="x"),0,"x") -> x | J58: =+'Room 1'!J58 -> Clean
A59: Floor | B59: =+IF(OR(C59="x",D59="x"),0,"x") -> x | J59: =+'Room 1'!J59 -> Carpet thoroughly vacuumed & free of debris & soiling - incl. corners / edges
A60: Bedroom Total | B60: =COUNTIF(B9:B59,"x") -> 49 | C60: =COUNTIF(C9:C59,"x") -> 0 | D60: =(COUNTIF(D9:D59,"x")*2)+(COUNTIF(D59,"x")+COUNTIF(D49,"x")+COUNTIF(D46,"x")+COUNTIF(D43,"x")+COUNTIF(D33,"x")+COUNTIF(D32,"x")+COUNTIF(D29,"x"))*2 -> 0 | F60: Perfect = 0 points, OK = 1 point, Not Acceptable (NA) = 2 points, Red boxes = 4 points
A62: Bathroom
B63: Perfect | C63: OK | D63: N/A | F63: Notes | J63: Looking for
A64: Hair Dryer | B64: =+IF(OR(C64="x",D64="x"),0,"x") -> x | J64: =+'Room 1'!J64 -> Clean & no lint or hair in filter screen
A65: Lotion Dispenser | B65: =+IF(OR(C65="x",D65="x"),0,"x") -> x | J65: =+'Room 1'!J65 -> Clean and adequately filled
A66: Mirror | B66: =+IF(OR(C66="x",D66="x"),0,"x") -> x | J66: =+'Room 1'!J66 -> No dust around edges, no spots or smudges on mirror
A67: Amenities | B67: =+IF(OR(C67="x",D67="x"),0,"x") -> x | J67: =+'Room 1'!J67 -> Properly stocked and presented
A68: Amenity Tray | B68: =+IF(OR(C68="x",D68="x"),0,"x") -> x | J68: =+'Room 1'!J68 -> Clean - top and on vanity underneath
...

Sheet Room 7
C1: General Manager Room Inspection
K2: Score | L2: % Perfect | M2: % OK | N2: % N/A
A3: Date | B3: 46168 | F3: Room Number | H3: 315 | J3: Housekeeping Score | K3: =+C60+D60+C90+D90 -> 1 | L3: =+(B60+B90)/75 -> 0.98666667 | M3: =+(C60+C90)/75 -> 0.013333333 | N3: =1-(L3+M3) -> 0
A5: Room Last Inspected by: | H5: pw = enterinfo | J5: Maintenance Score | K5: =C113+D113 -> 0 | L5: =+B113/19 -> 1 | M5: =+C113/17 -> 0 | N5: =1-(L5+M5) -> 0
A6: Bedroom
B8: Perfect | C8: OK | D8: N/A | F8: Notes | J8: Looking for
A9: Entry Door | B9: =+IF(OR(C9="x",D9="x"),0,"x") -> x | J9: =+'Room 1'!J9 -> Clean & free of scuffs
A10: Entry Light | B10: =+IF(OR(C10="x",D10="x"),0,"x") -> x | J10: =+'Room 1'!J10 -> Bulbs working, no bugs or debris
A11: Mirror | B11: =+IF(OR(C11="x",D11="x"),0,"x") -> x | J11: =+'Room 1'!J11 -> No streaks, no dust
A12: Trash Can | B12: =+IF(OR(C12="x",D12="x"),0,"x") -> x | J12: =+'Room 1'!J12 -> Clean & bag tied
A13: Behind trash can (Wall) | B13: =+IF(OR(C13="x",D13="x"),0,"x") -> x | J13: =+'Room 1'!J13 -> No soil spots on wall or furniture piece behind trash can
A14: Desk | B14: =+IF(OR(C14="x",D14="x"),0,"x") -> x | J14: =+'Room 1'!J14 -> Clean surface & no fingerprints
A15: Desk Chair | B15: =+IF(OR(C15="x",D15="x"),0,"x") -> x | J15: =+'Room 1'!J15 -> Seat / back clean, no dust on base
A16: TV / Media Board | B16: =+IF(OR(C16="x",D16="x"),0,"x") -> x | J16: =+'Room 1'!J16 -> No soiled spots
A17: Literature / Signage | B17: =+IF(OR(C17="x",D17="x"),0,"x") -> x | J17: =+'Room 1'!J17 -> Sat. & Hskpg card, Channel Guide & other - present & in perfect condition
A18: Coffee Tray / Brewer | B18: =+IF(OR(C18="x",D18="x"),0,"x") -> x | J18: =+'Room 1'!J18 -> Brewer clean inside & no debris or soiled spots on or below tray
A19: Ice Bucket | B19: =+IF(OR(C19="x",D19="x"),0,"x") -> x | J19: =+'Room 1'!J19 -> Clean inside and out with liner
A20: Coffee Amenities | B20: =+IF(OR(C20="x",D20="x"),0,"x") -> x | J20: =+'Room 1'!J20 -> Proper quantity of items & presented properly
... A46: Pillow cases | B46: =+IF(OR(C46="x",D46="x"),0,"x") -> x | J46: =+'Room 1'!J46 -> Not wrinkled, properly tuckeed & top corners pointed
A47: General Manager Room Inspection (Bedroom continued)
B48: Perfect | C48: OK | D48: N/A | F48: Notes | J48: Looking for
A49: Top Sheet | B49: =+IF(OR(C49="x",D49="x"),0,"x") -> x | J49: =+'Room 1'!J49 -> Pulled tight, not or minimally wrinkled, no stains
A50: Artwork 2 | B50: =+IF(OR(C50="x",D50="x"),0,"x") -> x | J50: =+'Room 1'!J50 -> No dust
A51: Nightstand 2 (if K) | B51: =+IF(OR(C51="x",D51="x"),0,"x") -> x | J51: =+'Room 1'!J51 -> Clean top surface, both sides, drawer and wall behind nightstand
A52: Sofa / Chair | B52: =+IF(OR(C52="x",D52="x"),0,"x") -> x | J52: =+'Room 1'!J52 -> No soiled cushions, zipper to back
A53: Sofa Sleeper | B53: =+IF(OR(C53="x",D53="x"),0,"x") -> x | J53: =+'Room 1'!J53 -> No dirty linen, mattress clean no debris underneath
A54: Coffee / End Table | B54: =+IF(OR(C54="x",D54="x"),0,"x") -> x | J54: =+'Room 1'!J54 -> Clean surface, no dust or soil on legs
A55: Wall | B55: =+IF(OR(C55="x",D55="x"),0,"x") -> x | J55: =+'Room 1'!J55 -> Not scuffed or soiled
A56: Closet (stocked) | B56: =+IF(OR(C56="x",D56="x"),0,"x") -> x | J56: =+'Room 1'!J56 -> Proper number of matching hangers, laundry bag
A57: Iron / Ironing Board | B57: =+IF(OR(C57="x",D57="x"),0,"x") -> x | J57: =+'Room 1'!J57 -> no water in iron, cord neatly wrapped, board cover not stained / soiled
A58: Closet Door | B58: =+IF(OR(C58="x",D58="x"),0,"x") -> x | J58: =+'Room 1'!J58 -> Clean
A59: Floor | B59: =+IF(OR(C59="x",D59="x"),0,"x") -> 0 | C59: X | J59: =+'Room 1'!J59 -> Carpet thoroughly vacuumed & free of debris & soiling - incl. corners / edges
A60: Bedroom Total | B60: =COUNTIF(B9:B59,"x") -> 48 | C60: =COUNTIF(C9:C59,"x") -> 1 | D60: =(COUNTIF(D9:D59,"x")*2)+(COUNTIF(D59,"x")+COUNTIF(D49,"x")+COUNTIF(D46,"x")+COUNTIF(D43,"x")+COUNTIF(D33,"x")+COUNTIF(D32,"x")+COUNTIF(D29,"x"))*2 -> 0 | F60: Perfect = 0 points, OK = 1 point, Not Acceptable (NA) = 2 points, Red boxes = 4 points
A62: Bathroom
B63: Perfect | C63: OK | D63: N/A | F63: Notes | J63: Looking for
A64: Hair Dryer | B64: =+IF(OR(C64="x",D64="x"),0,"x") -> x | J64: =+'Room 1'!J64 -> Clean & no lint or hair in filter screen
A65: Lotion Dispenser | B65: =+IF(OR(C65="x",D65="x"),0,"x") -> x | J65: =+'Room 1'!J65 -> Clean and adequately filled
A66: Mirror | B66: =+IF(OR(C66="x",D66="x"),0,"x") -> x | J66: =+'Room 1'!J66 -> No dust around edges, no spots or smudges on mirror
A67: Amenities | B67: =+IF(OR(C67="x",D67="x"),0,"x") -> x | J67: =+'Room 1'!J67 -> Properly stocked and presented
A68: Amenity Tray | B68: =+IF(OR(C68="x",D68="x"),0,"x") -> x | J68: =+'Room 1'!J68 -> Clean - top and on vanity underneath
...

Sheet Room 8
C1: General Manager Room Inspection
K2: Score | L2: % Perfect | M2: % OK | N2: % N/A
A3: Date | B3: 46168 | F3: Room Number | H3: 200 | J3: Housekeeping Score | K3: =+C60+D60+C90+D90 -> 1 | L3: =+(B60+B90)/75 -> 0.98666667 | M3: =+(C60+C90)/75 -> 0.013333333 | N3: =1-(L3+M3) -> 0
A5: Room Last Inspected by: | C5: Kelsey | H5: pw = enterinfo | J5: Maintenance Score | K5: =C113+D113 -> 0 | L5: =+B113/19 -> 1 | M5: =+C113/17 -> 0 | N5: =1-(L5+M5) -> 0
A6: Bedroom
B8: Perfect | C8: OK | D8: N/A | F8: Notes | J8: Looking for
A9: Entry Door | B9: =+IF(OR(C9="x",D9="x"),0,"x") -> x | J9: =+'Room 1'!J9 -> Clean & free of scuffs
A10: Entry Light | B10: =+IF(OR(C10="x",D10="x"),0,"x") -> x | J10: =+'Room 1'!J10 -> Bulbs working, no bugs or debris
A11: Mirror | B11: =+IF(OR(C11="x",D11="x"),0,"x") -> x | J11: =+'Room 1'!J11 -> No streaks, no dust
A12: Trash Can | B12: =+IF(OR(C12="x",D12="x"),0,"x") -> x | J12: =+'Room 1'!J12 -> Clean & bag tied
A13: Behind trash can (Wall) | B13: =+IF(OR(C13="x",D13="x"),0,"x") -> x | J13: =+'Room 1'!J13 -> No soil spots on wall or furniture piece behind trash can
A14: Desk | B14: =+IF(OR(C14="x",D14="x"),0,"x") -> x | J14: =+'Room 1'!J14 -> Clean surface & no fingerprints
A15: Desk Chair | B15: =+IF(OR(C15="x",D15="x"),0,"x") -> x | J15: =+'Room 1'!J15 -> Seat / back clean, no dust on base
A16: TV / Media Board | B16: =+IF(OR(C16="x",D16="x"),0,"x") -> x | J16: =+'Room 1'!J16 -> No soiled spots
A17: Literature / Signage | B17: =+IF(OR(C17="x",D17="x"),0,"x") -> x | J17: =+'Room 1'!J17 -> Sat. & Hskpg card, Channel Guide & other - present & in perfect condition
A18: Coffee Tray / Brewer | B18: =+IF(OR(C18="x",D18="x"),0,"x") -> x | J18: =+'Room 1'!J18 -> Brewer clean inside & no debris or soiled spots on or below tray
A19: Ice Bucket | B19: =+IF(OR(C19="x",D19="x"),0,"x") -> x | J19: =+'Room 1'!J19 -> Clean inside and out with liner
A20: Coffee Amenities | B20: =+IF(OR(C20="x",D20="x"),0,"x") -> x | J20: =+'Room 1'!J20 -> Proper quantity of items & presented properly
... A46: Pillow cases | B46: =+IF(OR(C46="x",D46="x"),0,"x") -> x | J46: =+'Room 1'!J46 -> Not wrinkled, properly tuckeed & top corners pointed
A47: General Manager Room Inspection (Bedroom continued)
B48: Perfect | C48: OK | D48: N/A | F48: Notes | J48: Looking for
A49: Top Sheet | B49: =+IF(OR(C49="x",D49="x"),0,"x") -> x | J49: =+'Room 1'!J49 -> Pulled tight, not or minimally wrinkled, no stains
A50: Artwork 2 | B50: =+IF(OR(C50="x",D50="x"),0,"x") -> x | J50: =+'Room 1'!J50 -> No dust
A51: Nightstand 2 (if K) | B51: =+IF(OR(C51="x",D51="x"),0,"x") -> x | J51: =+'Room 1'!J51 -> Clean top surface, both sides, drawer and wall behind nightstand
A52: Sofa / Chair | B52: =+IF(OR(C52="x",D52="x"),0,"x") -> x | J52: =+'Room 1'!J52 -> No soiled cushions, zipper to back
A53: Sofa Sleeper | B53: =+IF(OR(C53="x",D53="x"),0,"x") -> x | J53: =+'Room 1'!J53 -> No dirty linen, mattress clean no debris underneath
A54: Coffee / End Table | B54: =+IF(OR(C54="x",D54="x"),0,"x") -> x | J54: =+'Room 1'!J54 -> Clean surface, no dust or soil on legs
A55: Wall | B55: =+IF(OR(C55="x",D55="x"),0,"x") -> x | J55: =+'Room 1'!J55 -> Not scuffed or soiled
A56: Closet (stocked) | B56: =+IF(OR(C56="x",D56="x"),0,"x") -> x | J56: =+'Room 1'!J56 -> Proper number of matching hangers, laundry bag
A57: Iron / Ironing Board | B57: =+IF(OR(C57="x",D57="x"),0,"x") -> x | J57: =+'Room 1'!J57 -> no water in iron, cord neatly wrapped, board cover not stained / soiled
A58: Closet Door | B58: =+IF(OR(C58="x",D58="x"),0,"x") -> x | J58: =+'Room 1'!J58 -> Clean
A59: Floor | B59: =+IF(OR(C59="x",D59="x"),0,"x") -> 0 | C59: X | J59: =+'Room 1'!J59 -> Carpet thoroughly vacuumed & free of debris & soiling - incl. corners / edges
A60: Bedroom Total | B60: =COUNTIF(B9:B59,"x") -> 48 | C60: =COUNTIF(C9:C59,"x") -> 1 | D60: =(COUNTIF(D9:D59,"x")*2)+(COUNTIF(D59,"x")+COUNTIF(D49,"x")+COUNTIF(D46,"x")+COUNTIF(D43,"x")+COUNTIF(D33,"x")+COUNTIF(D32,"x")+COUNTIF(D29,"x"))*2 -> 0 | F60: Perfect = 0 points, OK = 1 point, Not Acceptable (NA) = 2 points, Red boxes = 4 points
A62: Bathroom
B63: Perfect | C63: OK | D63: N/A | F63: Notes | J63: Looking for
A64: Hair Dryer | B64: =+IF(OR(C64="x",D64="x"),0,"x") -> x | J64: =+'Room 1'!J64 -> Clean & no lint or hair in filter screen
A65: Lotion Dispenser | B65: =+IF(OR(C65="x",D65="x"),0,"x") -> x | J65: =+'Room 1'!J65 -> Clean and adequately filled
A66: Mirror | B66: =+IF(OR(C66="x",D66="x"),0,"x") -> x | J66: =+'Room 1'!J66 -> No dust around edges, no spots or smudges on mirror
A67: Amenities | B67: =+IF(OR(C67="x",D67="x"),0,"x") -> x | J67: =+'Room 1'!J67 -> Properly stocked and presented
A68: Amenity Tray | B68: =+IF(OR(C68="x",D68="x"),0,"x") -> x | J68: =+'Room 1'!J68 -> Clean - top and on vanity underneath
...

Sheet Room 9
C1: General Manager Room Inspection
K2: Score | L2: % Perfect | M2: % OK | N2: % N/A
A3: Date | F3: Room Number | J3: Housekeeping Score | K3: =+C60+D60+C90+D90 -> 0 | L3: =+(B60+B90)/75 -> 1 | M3: =+(C60+C90)/75 -> 0 | N3: =1-(L3+M3) -> 0
A5: Room Last Inspected by: | H5: pw = enterinfo | J5: Maintenance Score | K5: =C113+D113 -> 0 | L5: =+B113/19 -> 1 | M5: =+C113/17 -> 0 | N5: =1-(L5+M5) -> 0
A6: Bedroom
B8: Perfect | C8: OK | D8: N/A | F8: Notes | J8: Looking for
A9: Entry Door | B9: =+IF(OR(C9="x",D9="x"),0,"x") -> x | J9: =+'Room 1'!J9 -> Clean & free of scuffs
A10: Entry Light | B10: =+IF(OR(C10="x",D10="x"),0,"x") -> x | J10: =+'Room 1'!J10 -> Bulbs working, no bugs or debris
A11: Mirror | B11: =+IF(OR(C11="x",D11="x"),0,"x") -> x | J11: =+'Room 1'!J11 -> No streaks, no dust
A12: Trash Can | B12: =+IF(OR(C12="x",D12="x"),0,"x") -> x | J12: =+'Room 1'!J12 -> Clean & bag tied
A13: Behind trash can (Wall) | B13: =+IF(OR(C13="x",D13="x"),0,"x") -> x | J13: =+'Room 1'!J13 -> No soil spots on wall or furniture piece behind trash can
A14: Desk | B14: =+IF(OR(C14="x",D14="x"),0,"x") -> x | J14: =+'Room 1'!J14 -> Clean surface & no fingerprints
A15: Desk Chair | B15: =+IF(OR(C15="x",D15="x"),0,"x") -> x | J15: =+'Room 1'!J15 -> Seat / back clean, no dust on base
A16: TV / Media Board | B16: =+IF(OR(C16="x",D16="x"),0,"x") -> x | J16: =+'Room 1'!J16 -> No soiled spots
A17: Literature / Signage | B17: =+IF(OR(C17="x",D17="x"),0,"x") -> x | J17: =+'Room 1'!J17 -> Sat. & Hskpg card, Channel Guide & other - present & in perfect condition
A18: Coffee Tray / Brewer | B18: =+IF(OR(C18="x",D18="x"),0,"x") -> x | J18: =+'Room 1'!J18 -> Brewer clean inside & no debris or soiled spots on or below tray
A19: Ice Bucket | B19: =+IF(OR(C19="x",D19="x"),0,"x") -> x | J19: =+'Room 1'!J19 -> Clean inside and out with liner
A20: Coffee Amenities | B20: =+IF(OR(C20="x",D20="x"),0,"x") -> x | J20: =+'Room 1'!J20 -> Proper quantity of items & presented properly
... A46: Pillow cases | B46: =+IF(OR(C46="x",D46="x"),0,"x") -> x | J46: =+'Room 1'!J46 -> Not wrinkled, properly tuckeed & top corners pointed
A47: General Manager Room Inspection (Bedroom continued)
B48: Perfect | C48: OK | D48: N/A | F48: Notes | J48: Looking for
A49: Top Sheet | B49: =+IF(OR(C49="x",D49="x"),0,"x") -> x | J49: =+'Room 1'!J49 -> Pulled tight, not or minimally wrinkled, no stains
A50: Artwork 2 | B50: =+IF(OR(C50="x",D50="x"),0,"x") -> x | J50: =+'Room 1'!J50 -> No dust
A51: Nightstand 2 (if K) | B51: =+IF(OR(C51="x",D51="x"),0,"x") -> x | J51: =+'Room 1'!J51 -> Clean top surface, both sides, drawer and wall behind nightstand
A52: Sofa / Chair | B52: =+IF(OR(C52="x",D52="x"),0,"x") -> x | J52: =+'Room 1'!J52 -> No soiled cushions, zipper to back
A53: Sofa Sleeper | B53: =+IF(OR(C53="x",D53="x"),0,"x") -> x | J53: =+'Room 1'!J53 -> No dirty linen, mattress clean no debris underneath
A54: Coffee / End Table | B54: =+IF(OR(C54="x",D54="x"),0,"x") -> x | J54: =+'Room 1'!J54 -> Clean surface, no dust or soil on legs
A55: Wall | B55: =+IF(OR(C55="x",D55="x"),0,"x") -> x | J55: =+'Room 1'!J55 -> Not scuffed or soiled
A56: Closet (stocked) | B56: =+IF(OR(C56="x",D56="x"),0,"x") -> x | J56: =+'Room 1'!J56 -> Proper number of matching hangers, laundry bag
A57: Iron / Ironing Board | B57: =+IF(OR(C57="x",D57="x"),0,"x") -> x | J57: =+'Room 1'!J57 -> no water in iron, cord neatly wrapped, board cover not stained / soiled
A58: Closet Door | B58: =+IF(OR(C58="x",D58="x"),0,"x") -> x | J58: =+'Room 1'!J58 -> Clean
A59: Floor | B59: =+IF(OR(C59="x",D59="x"),0,"x") -> x | J59: =+'Room 1'!J59 -> Carpet thoroughly vacuumed & free of debris & soiling - incl. corners / edges
A60: Bedroom Total | B60: =COUNTIF(B9:B59,"x") -> 49 | C60: =COUNTIF(C9:C59,"x") -> 0 | D60: =(COUNTIF(D9:D59,"x")*2)+(COUNTIF(D59,"x")+COUNTIF(D49,"x")+COUNTIF(D46,"x")+COUNTIF(D43,"x")+COUNTIF(D33,"x")+COUNTIF(D32,"x")+COUNTIF(D29,"x"))*2 -> 0 | F60: Perfect = 0 points, OK = 1 point, Not Acceptable (NA) = 2 points, Red boxes = 4 points
A62: Bathroom
B63: Perfect | C63: OK | D63: N/A | F63: Notes | J63: Looking for
A64: Hair Dryer | B64: =+IF(OR(C64="x",D64="x"),0,"x") -> x | J64: =+'Room 1'!J64 -> Clean & no lint or hair in filter screen
A65: Lotion Dispenser | B65: =+IF(OR(C65="x",D65="x"),0,"x") -> x | J65: =+'Room 1'!J65 -> Clean and adequately filled
A66: Mirror | B66: =+IF(OR(C66="x",D66="x"),0,"x") -> x | J66: =+'Room 1'!J66 -> No dust around edges, no spots or smudges on mirror
A67: Amenities | B67: =+IF(OR(C67="x",D67="x"),0,"x") -> x | J67: =+'Room 1'!J67 -> Properly stocked and presented
A68: Amenity Tray | B68: =+IF(OR(C68="x",D68="x"),0,"x") -> x | J68: =+'Room 1'!J68 -> Clean - top and on vanity underneath
...

Sheet Room 10
C1: General Manager Room Inspection
K2: Score | L2: % Perfect | M2: % OK | N2: % N/A
A3: Date | F3: Room Number | J3: Housekeeping Score | K3: =+C60+D60+C90+D90 -> 0 | L3: =+(B60+B90)/75 -> 1 | M3: =+(C60+C90)/75 -> 0 | N3: =1-(L3+M3) -> 0
A5: Room Last Inspected by: | H5: pw = enterinfo | J5: Maintenance Score | K5: =C113+D113 -> 0 | L5: =+B113/19 -> 1 | M5: =+C113/17 -> 0 | N5: =1-(L5+M5) -> 0
A6: Bedroom
B8: Perfect | C8: OK | D8: N/A | F8: Notes | J8: Looking for
A9: Entry Door | B9: =+IF(OR(C9="x",D9="x"),0,"x") -> x | J9: =+'Room 1'!J9 -> Clean & free of scuffs
A10: Entry Light | B10: =+IF(OR(C10="x",D10="x"),0,"x") -> x | J10: =+'Room 1'!J10 -> Bulbs working, no bugs or debris
A11: Mirror | B11: =+IF(OR(C11="x",D11="x"),0,"x") -> x | J11: =+'Room 1'!J11 -> No streaks, no dust
A12: Trash Can | B12: =+IF(OR(C12="x",D12="x"),0,"x") -> x | J12: =+'Room 1'!J12 -> Clean & bag tied
A13: Behind trash can (Wall) | B13: =+IF(OR(C13="x",D13="x"),0,"x") -> x | J13: =+'Room 1'!J13 -> No soil spots on wall or furniture piece behind trash can
A14: Desk | B14: =+IF(OR(C14="x",D14="x"),0,"x") -> x | J14: =+'Room 1'!J14 -> Clean surface & no fingerprints
A15: Desk Chair | B15: =+IF(OR(C15="x",D15="x"),0,"x") -> x | J15: =+'Room 1'!J15 -> Seat / back clean, no dust on base
A16: TV / Media Board | B16: =+IF(OR(C16="x",D16="x"),0,"x") -> x | J16: =+'Room 1'!J16 -> No soiled spots
A17: Literature / Signage | B17: =+IF(OR(C17="x",D17="x"),0,"x") -> x | J17: =+'Room 1'!J17 -> Sat. & Hskpg card, Channel Guide & other - present & in perfect condition
A18: Coffee Tray / Brewer | B18: =+IF(OR(C18="x",D18="x"),0,"x") -> x | J18: =+'Room 1'!J18 -> Brewer clean inside & no debris or soiled spots on or below tray
A19: Ice Bucket | B19: =+IF(OR(C19="x",D19="x"),0,"x") -> x | J19: =+'Room 1'!J19 -> Clean inside and out with liner
A20: Coffee Amenities | B20: =+IF(OR(C20="x",D20="x"),0,"x") -> x | J20: =+'Room 1'!J20 -> Proper quantity of items & presented properly
... A46: Pillow cases | B46: =+IF(OR(C46="x",D46="x"),0,"x") -> x | J46: =+'Room 1'!J46 -> Not wrinkled, properly tuckeed & top corners pointed
A47: General Manager Room Inspection (Bedroom continued)
B48: Perfect | C48: OK | D48: N/A | F48: Notes | J48: Looking for
A49: Top Sheet | B49: =+IF(OR(C49="x",D49="x"),0,"x") -> x | J49: =+'Room 1'!J49 -> Pulled tight, not or minimally wrinkled, no stains
A50: Artwork 2 | B50: =+IF(OR(C50="x",D50="x"),0,"x") -> x | J50: =+'Room 1'!J50 -> No dust
A51: Nightstand 2 (if K) | B51: =+IF(OR(C51="x",D51="x"),0,"x") -> x | J51: =+'Room 1'!J51 -> Clean top surface, both sides, drawer and wall behind nightstand
A52: Sofa / Chair | B52: =+IF(OR(C52="x",D52="x"),0,"x") -> x | J52: =+'Room 1'!J52 -> No soiled cushions, zipper to back
A53: Sofa Sleeper | B53: =+IF(OR(C53="x",D53="x"),0,"x") -> x | J53: =+'Room 1'!J53 -> No dirty linen, mattress clean no debris underneath
A54: Coffee / End Table | B54: =+IF(OR(C54="x",D54="x"),0,"x") -> x | J54: =+'Room 1'!J54 -> Clean surface, no dust or soil on legs
A55: Wall | B55: =+IF(OR(C55="x",D55="x"),0,"x") -> x | J55: =+'Room 1'!J55 -> Not scuffed or soiled
A56: Closet (stocked) | B56: =+IF(OR(C56="x",D56="x"),0,"x") -> x | J56: =+'Room 1'!J56 -> Proper number of matching hangers, laundry bag
A57: Iron / Ironing Board | B57: =+IF(OR(C57="x",D57="x"),0,"x") -> x | J57: =+'Room 1'!J57 -> no water in iron, cord neatly wrapped, board cover not stained / soiled
A58: Closet Door | B58: =+IF(OR(C58="x",D58="x"),0,"x") -> x | J58: =+'Room 1'!J58 -> Clean
A59: Floor | B59: =+IF(OR(C59="x",D59="x"),0,"x") -> x | J59: =+'Room 1'!J59 -> Carpet thoroughly vacuumed & free of debris & soiling - incl. corners / edges
A60: Bedroom Total | B60: =COUNTIF(B9:B59,"x") -> 49 | C60: =COUNTIF(C9:C59,"x") -> 0 | D60: =(COUNTIF(D9:D59,"x")*2)+(COUNTIF(D59,"x")+COUNTIF(D49,"x")+COUNTIF(D46,"x")+COUNTIF(D43,"x")+COUNTIF(D33,"x")+COUNTIF(D32,"x")+COUNTIF(D29,"x"))*2 -> 0 | F60: Perfect = 0 points, OK = 1 point, Not Acceptable (NA) = 2 points, Red boxes = 4 points
A62: Bathroom
B63: Perfect | C63: OK | D63: N/A | F63: Notes | J63: Looking for
A64: Hair Dryer | B64: =+IF(OR(C64="x",D64="x"),0,"x") -> x | J64: =+'Room 1'!J64 -> Clean & no lint or hair in filter screen
A65: Lotion Dispenser | B65: =+IF(OR(C65="x",D65="x"),0,"x") -> x | J65: =+'Room 1'!J65 -> Clean and adequately filled
A66: Mirror | B66: =+IF(OR(C66="x",D66="x"),0,"x") -> x | J66: =+'Room 1'!J66 -> No dust around edges, no spots or smudges on mirror
A67: Amenities | B67: =+IF(OR(C67="x",D67="x"),0,"x") -> x | J67: =+'Room 1'!J67 -> Properly stocked and presented
A68: Amenity Tray | B68: =+IF(OR(C68="x",D68="x"),0,"x") -> x | J68: =+'Room 1'!J68 -> Clean - top and on vanity underneath
...

Sheet Room 11
C1: General Manager Room Inspection
K2: Score | L2: % Perfect | M2: % OK | N2: % N/A
A3: Date | F3: Room Number | J3: Housekeeping Score | K3: =+C60+D60+C90+D90 -> 0 | L3: =+(B60+B90)/75 -> 1 | M3: =+(C60+C90)/75 -> 0 | N3: =1-(L3+M3) -> 0
A5: Room Last Inspected by: | H5: pw = enterinfo | J5: Maintenance Score | K5: =C113+D113 -> 0 | L5: =+B113/19 -> 1 | M5: =+C113/17 -> 0 | N5: =1-(L5+M5) -> 0
A6: Bedroom
B8: Perfect | C8: OK | D8: N/A | F8: Notes | J8: Looking for
A9: Entry Door | B9: =+IF(OR(C9="x",D9="x"),0,"x") -> x | J9: =+'Room 1'!J9 -> Clean & free of scuffs
A10: Entry Light | B10: =+IF(OR(C10="x",D10="x"),0,"x") -> x | J10: =+'Room 1'!J10 -> Bulbs working, no bugs or debris
A11: Mirror | B11: =+IF(OR(C11="x",D11="x"),0,"x") -> x | J11: =+'Room 1'!J11 -> No streaks, no dust
A12: Trash Can | B12: =+IF(OR(C12="x",D12="x"),0,"x") -> x | J12: =+'Room 1'!J12 -> Clean & bag tied
A13: Behind trash can (Wall) | B13: =+IF(OR(C13="x",D13="x"),0,"x") -> x | J13: =+'Room 1'!J13 -> No soil spots on wall or furniture piece behind trash can
A14: Desk | B14: =+IF(OR(C14="x",D14="x"),0,"x") -> x | J14: =+'Room 1'!J14 -> Clean surface & no fingerprints
A15: Desk Chair | B15: =+IF(OR(C15="x",D15="x"),0,"x") -> x | J15: =+'Room 1'!J15 -> Seat / back clean, no dust on base
A16: TV / Media Board | B16: =+IF(OR(C16="x",D16="x"),0,"x") -> x | J16: =+'Room 1'!J16 -> No soiled spots
A17: Literature / Signage | B17: =+IF(OR(C17="x",D17="x"),0,"x") -> x | J17: =+'Room 1'!J17 -> Sat. & Hskpg card, Channel Guide & other - present & in perfect condition
A18: Coffee Tray / Brewer | B18: =+IF(OR(C18="x",D18="x"),0,"x") -> x | J18: =+'Room 1'!J18 -> Brewer clean inside & no debris or soiled spots on or below tray
A19: Ice Bucket | B19: =+IF(OR(C19="x",D19="x"),0,"x") -> x | J19: =+'Room 1'!J19 -> Clean inside and out with liner
A20: Coffee Amenities | B20: =+IF(OR(C20="x",D20="x"),0,"x") -> x | J20: =+'Room 1'!J20 -> Proper quantity of items & presented properly
... A46: Pillow cases | B46: =+IF(OR(C46="x",D46="x"),0,"x") -> x | J46: =+'Room 1'!J46 -> Not wrinkled, properly tuckeed & top corners pointed
A47: General Manager Room Inspection (Bedroom continued)
B48: Perfect | C48: OK | D48: N/A | F48: Notes | J48: Looking for
A49: Top Sheet | B49: =+IF(OR(C49="x",D49="x"),0,"x") -> x | J49: =+'Room 1'!J49 -> Pulled tight, not or minimally wrinkled, no stains
A50: Artwork 2 | B50: =+IF(OR(C50="x",D50="x"),0,"x") -> x | J50: =+'Room 1'!J50 -> No dust
A51: Nightstand 2 (if K) | B51: =+IF(OR(C51="x",D51="x"),0,"x") -> x | J51: =+'Room 1'!J51 -> Clean top surface, both sides, drawer and wall behind nightstand
A52: Sofa / Chair | B52: =+IF(OR(C52="x",D52="x"),0,"x") -> x | J52: =+'Room 1'!J52 -> No soiled cushions, zipper to back
A53: Sofa Sleeper | B53: =+IF(OR(C53="x",D53="x"),0,"x") -> x | J53: =+'Room 1'!J53 -> No dirty linen, mattress clean no debris underneath
A54: Coffee / End Table | B54: =+IF(OR(C54="x",D54="x"),0,"x") -> x | J54: =+'Room 1'!J54 -> Clean surface, no dust or soil on legs
A55: Wall | B55: =+IF(OR(C55="x",D55="x"),0,"x") -> x | J55: =+'Room 1'!J55 -> Not scuffed or soiled
A56: Closet (stocked) | B56: =+IF(OR(C56="x",D56="x"),0,"x") -> x | J56: =+'Room 1'!J56 -> Proper number of matching hangers, laundry bag
A57: Iron / Ironing Board | B57: =+IF(OR(C57="x",D57="x"),0,"x") -> x | J57: =+'Room 1'!J57 -> no water in iron, cord neatly wrapped, board cover not stained / soiled
A58: Closet Door | B58: =+IF(OR(C58="x",D58="x"),0,"x") -> x | J58: =+'Room 1'!J58 -> Clean
A59: Floor | B59: =+IF(OR(C59="x",D59="x"),0,"x") -> x | J59: =+'Room 1'!J59 -> Carpet thoroughly vacuumed & free of debris & soiling - incl. corners / edges
A60: Bedroom Total | B60: =COUNTIF(B9:B59,"x") -> 49 | C60: =COUNTIF(C9:C59,"x") -> 0 | D60: =(COUNTIF(D9:D59,"x")*2)+(COUNTIF(D59,"x")+COUNTIF(D49,"x")+COUNTIF(D46,"x")+COUNTIF(D43,"x")+COUNTIF(D33,"x")+COUNTIF(D32,"x")+COUNTIF(D29,"x"))*2 -> 0 | F60: Perfect = 0 points, OK = 1 point, Not Acceptable (NA) = 2 points, Red boxes = 4 points
A62: Bathroom
B63: Perfect | C63: OK | D63: N/A | F63: Notes | J63: Looking for
A64: Hair Dryer | B64: =+IF(OR(C64="x",D64="x"),0,"x") -> x | J64: =+'Room 1'!J64 -> Clean & no lint or hair in filter screen
A65: Lotion Dispenser | B65: =+IF(OR(C65="x",D65="x"),0,"x") -> x | J65: =+'Room 1'!J65 -> Clean and adequately filled
A66: Mirror | B66: =+IF(OR(C66="x",D66="x"),0,"x") -> x | J66: =+'Room 1'!J66 -> No dust around edges, no spots or smudges on mirror
A67: Amenities | B67: =+IF(OR(C67="x",D67="x"),0,"x") -> x | J67: =+'Room 1'!J67 -> Properly stocked and presented
A68: Amenity Tray | B68: =+IF(OR(C68="x",D68="x"),0,"x") -> x | J68: =+'Room 1'!J68 -> Clean - top and on vanity underneath
...

Sheet Room 12
C1: General Manager Room Inspection
K2: Score | L2: % Perfect | M2: % OK | N2: % N/A
A3: Date | F3: Room Number | J3: Housekeeping Score | K3: =+C60+D60+C90+D90 -> 0 | L3: =+(B60+B90)/75 -> 1 | M3: =+(C60+C90)/75 -> 0 | N3: =1-(L3+M3) -> 0
