Workbook

Sheet Instructions
C3: Follow these simple steps to set up your hotel & use the easy linen inventory workbook.
A5: Begin by completing the Hotel Set Up page.
A7: 1st, enter your room type counts. This can be obtained from your hotel property management system.
A9: 2nd, enter your desired level of PAR. This is the number of turns you of linen you will need. Remember, higher PAR levels = longer linen life &
A10: Less loss of productivity for the department.
A12: 3rd, enter the number of FLAT sheets used per made bed. Do this for both KNG & TDB.
A13: Are you using FITTED sheets? If so, indicate it. The worksheet will calculate these totals for you as well.
A15: 4th, don't forget the sofa sleeper counts!!
A17: The second step in setting up the worksheet is to proceed to the tab titled "Total Linen March 31st".
A18: Enter the COST PER UNIT for each linen item on the Total Linen form. This will allow the form to calculate the value of your inventory
A19: and how much the needed linen will cost. You can only do this on the March 31st worksheet. The price per item will copy to each
A20: of the following quarters and remain consistent for the entire year. Even though prices may fluctuate throughout the year, we do not
A21: want our inventory values to shrink or grow based on price changes.
... A31: Using the "Save As" function, save your Linen Worksheet using the file naming format
B32: LinenInventory_PropertyName_Year
A34: It will be very important for you to record all purchases into the Purchase Log form. Failure to do this will result in a lot of work later.
A35: Each quarters totals will be added to the Total Linen worksheet for the respective quarter as you enter purchase quantities into .
A36: the "Purchase Log"
A38: The Inventory Process
A40: Print the Storage Count Form. Make as many copies of this form as needed & distribute to counters/room attendants. This where they
A41: should record the linen counts from each storage room. Since the form is similar to the Storage Worksheet, it will make input of these totals simple.
A42: Using the Storage Count Form and entering it on the Storage Worksheet will be easier than entering it directly on the Total Linen page.
A44: Once all storage areas have been counted, enter the values from each Storage Count Form into the worksheet titled "Storage Worksheet"
A46: Once all of the Storage Count Forms have been entered, enter the numbers from the total line on the Storage Worksheet into line 5 titled
A47: "in storage" on the "Total Linen" worksheet for the appropriate quarter. Before the worksheet will allow you to enter any values, it will ask
A48: you for a password. The password for all cells that you are allowed to modify is "hotel" (enter it without the quotation marks). | M48: You are not
A49: allowed to modify certain cells, so if your "hotel" password doesn't work, you're trying to type into a cell that's protected. If you identify a formula
A50: problem in the worksheet, call me and I will fix it for you.
A52: The only totals left for input are the dirty counts in laundry and clean laundry on carts. Count those items and enter them into line 6 titled "Laundry"
A53: on the quarterly "Total Linen" worksheet.
A55: Once this is done, your inventory process is complete.
A57: It is important to know that you are only allowed to modify the yellow colored cells. All of the other cells are protected
A58: with a different password. If you need to change other cells anywhere else in the worksheet, contact Bill Michaud.
A62: Review the Results
A63: Once you have completed the worksheet, review the shortage lines.
B64: Look for significant shortages that didn't exist in the prior quarter.
B65: How confident are you that every purchase invoice was entered?
C66: Double check this if cells turned red on the worksheet.
A68: Print a copy of this worksheet for regular use in determining your ongoing purchasing needs.
A70: Make a plan to reduce loss so that purchases grow the inventory closer to PAR rather than
...

Sheet Hotel Set up
B2: Enter Property Name and other Details in the Hotel Setup Tab
C4: Room Type Counts | J4: password = hotel
B5: 1st | C5: Type | D5: Qty | E5: 2nd | H5: 3rd
B6: Room Types w/ 1 King bed | C6: KNG | D6: 0 | F6: Enter desired PAR | I6: How many flat sheets | M6: Pillows per bed
C7: NK | D7: 0 | F7: level below: | I7: per bed ? | M7: soft | N7: firm
C8: HNK1 | D8: 0 | F8: (e.g. 2.5 or 3 turns) | I8: KNG | J8: 1 | K8: (triple sheet?) | L8: KNG | M8: 5 | N8: 5
C9: SHNK | D9: 0 | F9: 2.5 | G9: Linens | I9: QQ | J9: 1 | L9: QQ | M9: 4 | N9: 4
C10: HNK1 | D10: 0 | F10: 1.1 | G10: Pillows & Blankets
C11: Type | D11: Qty
B12: Room Types w/ 2 Queen beds | C12: QQ | D12: 0 | I12: And Bath Linen ?
C13: HNQQ | D13: 0 | I13: Count per room: | J13: Kings | K13: Queens
C14: QQ | D14: 0 | I14: Hand | J14: 2 | K14: 2
C15: QQ | D15: 0 | I15: Bath | J15: 2 | K15: 4
C16: QQ | D16: 0 | I16: Facial | J16: 3 | K16: 4
C18: TTL King | D18: =SUM(D6:D10) -> 0 | F18: 4th | L18: Set Contents
C19: TTL QQ | D19: =SUM(D12:D16) -> 0 | F19: Don't forget Sofa Sleepers!! How many ? | J19: 15 | L19: King | M19: Queen
H20: Queent Fitted | J20: 1 | K20: Flat | L20: 1 | M20: 1
C21: TTL Count | D21: =SUM(D6:D16) -> 0 | H21: Queen Flat | J21: 1 | K21: Fitted | L21: 1 | M21: 1
B22: Should be equal to the total room count for your hotel | F22: Cribs | G22: Rollaways | H22: Blanket | J22: 1 | K22: Firm Case | L22: 1 | M22: 1
F23: 1 | G23: 1 | H23: Pillow Case | J23: 1 | K23: Soft Case | L23: 1 | M23: 1

Sheet Purchase Log
E1: Bath Linen
C2: Bath Linen | H2: Kings | M2: Queens | R2: Full / Sofa Sleepers | V2: Pillow Cases
A3: Month of Invoice Date | B3: Invoice Number | C3: Wash | D3: Hand | E3: Bath | F3: Bath | H3: Flat Sheet | I3: Fitted Sheet | J3: Duvet / Blanket | K3: Duvet Cover / Top Spread | M3: Flat Sheet | N3: Fitted Sheet | O3: Duvet / Blanket | P3: Duvet Cover / Top Spread | R3: Flat Sheets | S3: Fitted Sheets | T3: Blankets | V3: King Firm Pillow Cases | W3: King Soft Pillow Cases | X3: Queen Firm Pillow Cases | Y3: Queen Soft Pillow Cases
C4: Clothes | D4: Towels | E4: Towels | F4: Mats
A10: Quarter 1 Total | C10: =SUM(C5:C9) -> 0 | D10: =SUM(D5:D9) -> 0 | E10: =SUM(E5:E9) -> 0 | F10: =SUM(F5:F9) -> 0 | G10: =SUM(G5:G9) -> 0 | H10: =SUM(H5:H9) -> 0 | I10: =SUM(I5:I9) -> 0 | J10: =SUM(J5:J9) -> 0 | ... P10: =SUM(P5:P9) -> 0 | R10: =SUM(R5:R9) -> 0 | S10: =SUM(S5:S9) -> 0 | T10: =SUM(T5:T9) -> 0 | U10: =SUM(U5:U9) -> 0 | V10: =SUM(V5:V9) -> 0 | W10: =SUM(W5:W9) -> 0 | X10: =SUM(X5:X9) -> 0 | Y10: =SUM(Y5:Y9) -> 0
A16: Quarter 2 Total | C16: =SUM(C11:C15) -> 0 | D16: =SUM(D11:D15) -> 0 | E16: =SUM(E11:E15) -> 0 | F16: =SUM(F11:F15) -> 0 | G16: =SUM(G11:G15) -> 0 | H16: 0 | I16: =SUM(I11:I15) -> 0 | J16: =SUM(J11:J15) -> 0 | K16: =SUM(K11:K15) -> 0 | L16: =SUM(L11:L15) -> 0 | M16: =SUM(M11:M15) -> 0 | N16: =SUM(N11:N15) -> 0 | O16: =SUM(O11:O15) -> 0 | P16: =SUM(P11:P15) -> 0 | R16: =SUM(R11:R15) -> 0 | S16: =SUM(S11:S15) -> 0 | T16: =SUM(T11:T15) -> 0 | U16: =SUM(U11:U15) -> 0 | V16: =SUM(V11:V15) -> 0 | W16: =SUM(W11:W15) -> 0 | X16: =SUM(X11:X15) -> 0 | Y16: =SUM(Y11:Y15) -> 0
A22: Quarter 3 Total | C22: =SUM(C17:C21) -> 0 | D22: =SUM(D17:D21) -> 0 | E22: =SUM(E17:E21) -> 0 | F22: =SUM(F17:F21) -> 0 | G22: =SUM(G17:G21) -> 0 | H22: =SUM(H17:H21) -> 0 | I22: =SUM(I17:I21) -> 0 | J22: =SUM(J17:J21) -> 0 | ... P22: =SUM(P17:P21) -> 0 | R22: =SUM(R17:R21) -> 0 | S22: =SUM(S17:S21) -> 0 | T22: =SUM(T17:T21) -> 0 | U22: =SUM(U17:U21) -> 0 | V22: =SUM(V17:V21) -> 0 | W22: =SUM(W17:W21) -> 0 | X22: =SUM(X17:X21) -> 0 | Y22: =SUM(Y17:Y21) -> 0
A28: Quarter 4 Total | C28: =SUM(C23:C27) -> 0 | D28: =SUM(D23:D27) -> 0 | E28: =SUM(E23:E27) -> 0 | F28: =SUM(F23:F27) -> 0 | G28: =SUM(G23:G27) -> 0 | H28: =SUM(H23:H27) -> 0 | I28: =SUM(I23:I27) -> 0 | J28: =SUM(J23:J27) -> 0 | ... P28: =SUM(P23:P27) -> 0 | R28: =SUM(R23:R27) -> 0 | S28: =SUM(S23:S27) -> 0 | T28: =SUM(T23:T27) -> 0 | U28: =SUM(U23:U27) -> 0 | V28: =SUM(V23:V27) -> 0 | W28: =SUM(W23:W27) -> 0 | X28: =SUM(X23:X27) -> 0 | Y28: =SUM(Y23:Y27) -> 0
A29: Total Annual Purchases | C29: =+C10+C16+C22+C28 -> 0 | D29: =+D10+D16+D22+D28 -> 0 | E29: =+E10+E16+E22+E28 -> 0 | F29: =+F10+F16+F22+F28 -> 0 | G29: =+G10+G16+G22+G28 -> 0 | H29: =+H10+H16+H22+H28 -> 0 | I29: =+I10+I16+I22+I28 -> 0 | J29: =+J10+J16+J22+J28 -> 0 | ... P29: =+P10+P16+P22+P28 -> 0 | R29: =+R10+R16+R22+R28 -> 0 | S29: =+S10+S16+S22+S28 -> 0 | T29: =+T10+T16+T22+T28 -> 0 | V29: =+V10+V16+V22+V28 -> 0 | W29: =+W10+W16+W22+W28 -> 0 | X29: =+X10+X16+X22+X28 -> 0 | Y29: =+Y10+Y16+Y22+Y28 -> 0
A31: Unit Cost | C31: =+'Total Linen March 31st'!B15 -> 0 | D31: =+'Total Linen March 31st'!C15 -> 0 | E31: =+'Total Linen March 31st'!D15 -> 0 | F31: =+'Total Linen March 31st'!E15 -> 0 | G31: =+'Total Linen March 31st'!F15 -> 0 | H31: =+'Total Linen March 31st'!G15 -> 0 | I31: =+'Total Linen March 31st'!H15 -> 0 | J31: =+'Total Linen March 31st'!I15 -> 0 | ... Y31: =+'Total Linen March 31st'!X15 -> 0
A33: Annual Spend | C33: =+C29*C31 -> 0 | D33: =+D29*D31 -> 0 | E33: =+E29*E31 -> 0 | F33: =+F29*F31 -> 0 | G33: =+G29*G31 -> 0 | H33: =+H29*H31 -> 0 | I33: =+I29*I31 -> 0 | J33: =+J29*J31 -> 0 | ... Y33: =+Y29*Y31 -> 0
A35: Approximated annual linen expenditure | E35: =SUM(C33:Y33) -> 0

Sheet Storage Count Form
J1: Storage Count Form
N2: Rotational linen | X2: print on legal paper to include the "Other Items" section on the page. | AE2: Non-rotational items
D3: Bath Linen | F3: Kings | K3: Queens | P3: Full / Sofa Sleepers | S3: Pillow Cases | X3: Other Items
B4: Wash Cloths | C4: Hand Towels | D4: Bath Towels | E4: Bath Mats | F4: King Sets | G4: Flat Sheet | H4: Fitted Sheet | I4: Duvet / Blanket | J4: Duvet Cover / Top Spread | K4: Queen Sets | L4: Flat Sheet | M4: Fitted Sheet | N4: Duvet / Blanket | O4: Duvet Cover / Top Spread | P4: Flat Sheet | Q4: Fitted Sheets | R4: Blankets | S4: King Firm Pillow Cases | T4: King Soft Pillow Cases | U4: Queen Firm Pillow Cases | V4: Queen Soft Pillow Cases | X4: King Firm Pillows | Y4: King Soft Pillows | Z4: Queen Firm Pillows | AA4: Queen Soft Pillows | AB4: King Mattress Pads | AC4: Queen Mattress Pads | AD4: Shower Curtains | AE4: Rollaway Sets | AF4: Crib Sets | AG4: Pool Towels
A6: Laundry Room
A7: 2nd Floor Closet
A8: 3rd Floor Closet
A9: Cart 1
A10: Cart 2
A11: Cart 3
A12: Cart 4
A13: Pool
A14: Fitness Center
A16: Totals | B16: =SUM(B6:B15) -> 0 | C16: =SUM(C6:C15) -> 0 | D16: =SUM(D6:D15) -> 0 | E16: =SUM(E6:E15) -> 0 | F16: =SUM(F6:F15) -> 0 | G16: =SUM(G6:G15)+F16*'Hotel Set up'!L20 -> 0 | H16: =SUM(H6:H15)+F16*'Hotel Set up'!L20 -> 0 | I16: =SUM(I6:I15) -> 0 | J16: =SUM(J6:J15) -> 0 | K16: =SUM(K6:K15) -> 0 | L16: =SUM(L6:L15)+K16*'Hotel Set up'!M20 -> 0 | M16: =SUM(M6:M15)+K16*'Hotel Set up'!M21 -> 0 | N16: =SUM(N6:N15) -> 0 | O16: =SUM(O6:O15) -> 0 | P16: =SUM(P6:P15) -> 0 | Q16: =SUM(Q6:Q15) -> 0 | R16: =SUM(R6:R15) -> 0 | S16: =SUM(S6:S15)+F16*'Hotel Set up'!L22 -> 0 | T16: =SUM(T6:T15)+F16*'Hotel Set up'!L23 -> 0 | U16: =SUM(U6:U15)+K16*'Hotel Set up'!M22 -> 0 | V16: =SUM(V6:V15)+K16*'Hotel Set up'!M23 -> 0 | X16: =SUM(X6:X15) -> 0 | Y16: =SUM(Y6:Y15) -> 0 | Z16: =SUM(Z6:Z15) -> 0 | AA16: =SUM(AA6:AA15) -> 0 | AB16: =SUM(AB6:AB15) -> 0 | AC16: =SUM(AC6:AC15) -> 0 | AD16: =SUM(AD6:AD15) -> 0 | AE16: =SUM(AE6:AE15) -> 0 | ... AH16: =SUM(AH6:AH15) -> 0
F17: Counts for the sets are formulated to be added into the itemized columns for the set contents based upon the details in the Hotel Set Up tab. You will not enter sets into the quarterly sheets. | T17: Number in rooms | X17: =+'Hotel Set up'!N8*'Hotel Set up'!D18 -> 0 | Y17: =+'Hotel Set up'!D18*'Hotel Set up'!M8 -> 0 | Z17: =+'Hotel Set up'!N9*'Hotel Set up'!D19*2 -> 0 | AA17: =(+'Hotel Set up'!M9*'Hotel Set up'!D19*2)+'Hotel Set up'!J19 -> 15 | AB17: =+'Hotel Set up'!D18 -> 0 | AC17: =+'Hotel Set up'!D19*2 -> 0 | AD17: =+'Hotel Set up'!D19 -> 0 | AE17: 0 | AF17: 0 | AG17: 0
T19: Total Count | X19: =+X16+X17 -> 0 | Y19: =+Y16+Y17 -> 0 | Z19: =+Z16+Z17 -> 0 | AA19: =+AA16+AA17 -> 15 | AB19: =+AB16+AB17 -> 0 | AC19: =+AC16+AC17 -> 0 | AD19: =+AD16+AD17 -> 0 | AE19: =+AE16+AE17 -> 0 | ... AH19: =+AH16+AH17 -> 0
A20: Supervisor Responsible for Count | H20: 1) Ensure all areas of the hotel where linen needs to be counted are identified in column A. | T20: Other Items Par Levels | X20: =+'Hotel Set up'!M8*'Hotel Set up'!F10*'Hotel Set up'!D18 -> 0 | Y20: =+'Hotel Set up'!M8*'Hotel Set up'!D18*'Hotel Set up'!F10 -> 0 | Z20: =+'Hotel Set up'!N9*'Hotel Set up'!D19*2*'Hotel Set up'!F10 -> 0 | AA20: =+'Hotel Set up'!M9*'Hotel Set up'!D19*2*'Hotel Set up'!F10 -> 0 | AB20: =+'Hotel Set up'!D18*'Hotel Set up'!F10 -> 0 | AC20: =+'Hotel Set up'!D19*2*'Hotel Set up'!F10 -> 0 | AD20: 0 | AE20: =+'Hotel Set up'!F23+2 -> 3 | AF20: =+'Hotel Set up'!F23+2 -> 3 | AG20: =+'Hotel Set up'!F23*'Hotel Set up'!F10 -> 1.1 | AH20: 0
H21: 2) Print blank Storage Count Form - as many as needed for the # of people participating in the count | T21: Variance vs PAR | X21: =+X16-X20 -> 0 | Y21: =+Y16-Y20 -> 0 | Z21: =+Z16-Z20 -> 0 | AA21: =+AA16-AA20 -> 0 | AB21: =+AB16-AB20 -> 0 | AC21: =+AC16-AC20 -> 0 | AD21: =+AD16-AD20 -> 0 | AE21: =+AE16-AE20 -> -3 | ... AH21: =+AH16-AH20 -> 0
H22: 3) Write the values into the proper cells as items are counted
A23: Signature______________________________________ | H23: 4) Once inventory of all locations is completed, enter the data into the storage worksheet and print.
H24: 5) Leave values in sheet for reference throughout the following quarter
A25: Date ________________________________ | H25: 6) When it's time for the next inventory to be taken, delete all the values from the body of the form.

Sheet Total Linen March 31st
A1: =+'Hotel Set up'!B2 -> Enter Property Name and other Details in the Hotel Setup Tab
B3: 1st Quarter
B4: Bath Linen | G4: Kings | L4: Queens | Q4: Full / Sofa Sleepers | U4: Pillowcases
B5: Wash Cloths | C5: Hand Towels | D5: Bath Towels | E5: Bath Mats | G5: Flat Sheets | H5: Fitted Sheets | I5: Duvets / Comforters | J5: Duvet Cover / Top Spread | L5: Flat Sheets | M5: Fitted Sheet | N5: Duvets / Comforters | O5: Duvet Cover / Top Spread | Q5: Blanket / Throw | R5: Flat Sheets | S5: Fitted Sheets | U5: King Firm | V5: King Soft | W5: Queen Firm | X5: Queen Soft
A7: In Room PAR | B7: =+('Hotel Set up'!J16*'Hotel Set up'!D18)+('Hotel Set up'!K16*'Hotel Set up'!D19) -> 0 | C7: =+'Hotel Set up'!J14*'Hotel Set up'!D18+'Hotel Set up'!K14*'Hotel Set up'!D19 -> 0 | D7: =+'Hotel Set up'!J15*'Hotel Set up'!D18+'Hotel Set up'!K15*'Hotel Set up'!D19 -> 0 | E7: ='Hotel Set up'!D21 -> 0 | G7: ='Hotel Set up'!D18*'Hotel Set up'!J8 -> 0 | H7: =+'Hotel Set up'!J8*'Hotel Set up'!D18 -> 0 | I7: ='Hotel Set up'!D18 -> 0 | J7: ='Hotel Set up'!D18 -> 0 | L7: =+('Hotel Set up'!D19*2)+'Hotel Set up'!J19 -> 15 | M7: =('Hotel Set up'!D19*2)+'Hotel Set up'!J19 -> 15 | N7: =('Hotel Set up'!D19*2)+'Hotel Set up'!J19 -> 15 | O7: ='Hotel Set up'!D19*2 -> 0 | Q7: =+'Hotel Set up'!J19 -> 15 | R7: =+'Hotel Set up'!J19 -> 15 | S7: =+'Hotel Set up'!J19 -> 15 | U7: =+'Hotel Set up'!N8*'Hotel Set up'!D18 -> 0 | V7: =+'Hotel Set up'!M8*'Hotel Set up'!D18 -> 0 | W7: =+('Hotel Set up'!$N$8*'Hotel Set up'!$D$18)+('Hotel Set up'!$N$9*'Hotel Set up'!$D$19) -> 0 | X7: =+('Hotel Set up'!$M$8*'Hotel Set up'!$D$18)+('Hotel Set up'!$M$9*'Hotel Set up'!$D$19)+'Hotel Set up'!J19 -> 15
A8: From Storage Count
A10: Inventory Total | B10: =SUM(B7:B8) -> 0 | C10: =SUM(C7:C8) -> 0 | D10: =SUM(D7:D8) -> 0 | E10: =SUM(E7:E8) -> 0 | G10: =SUM(G7:G8) -> 0 | H10: =SUM(H7:H8) -> 0 | I10: =SUM(I7:I8) -> 0 | J10: =SUM(J7:J8) -> 0 | L10: =SUM(L7:L8) -> 15 | M10: =SUM(M7:M8) -> 15 | N10: =SUM(N7:N8) -> 15 | O10: =SUM(O7:O8) -> 0 | Q10: =SUM(Q7:Q8) -> 15 | R10: =SUM(R7:R8) -> 15 | S10: =SUM(S7:S8) -> 15 | U10: =SUM(U7:U8) -> 0 | V10: =SUM(V7:V8) -> 0 | W10: =SUM(W7:W8) -> 0 | X10: =SUM(X7:X8) -> 15
A12: Par Level | B12: =+B7*2.5 -> 0 | C12: =+C7*2.5 -> 0 | D12: =+D7*2.5 -> 0 | E12: =+E7*2.5 -> 0 | G12: =+G7*2.5 -> 0 | H12: =+H7*2.5 -> 0 | I12: =+I7*2.5 -> 0 | J12: =+J7*2.5 -> 0 | L12: =+(('Hotel Set up'!D19*2)*'Hotel Set up'!F9)+'Hotel Set up'!J19 -> 15 | M12: =+('Hotel Set up'!$D$19*2*'Hotel Set up'!$F$9)+'Hotel Set up'!$J$19 -> 15 | N12: =+N7*2.5 -> 37.5 | O12: =+O7*2.5 -> 0 | Q12: =+Q7*2.5 -> 37.5 | R12: =+R7*2.5 -> 37.5 | S12: =+S7*2.5 -> 37.5 | U12: =+U7*2.5 -> 0 | V12: =+V7*2.5 -> 0 | W12: =+W7*2.5 -> 0 | X12: =+X7*2.5 -> 37.5
A13: Inventory Variance | B13: =B10-B12 -> 0 | C13: =C10-C12 -> 0 | D13: =D10-D12 -> 0 | E13: =E10-E12 -> 0 | G13: =G10-G12 -> 0 | H13: =H10-H12 -> 0 | I13: =I10-I12 -> 0 | J13: =J10-J12 -> 0 | L13: =L10-L12 -> 0 | M13: =M10-M12 -> 0 | N13: =N10-N12 -> -22.5 | O13: =O10-O12 -> 0 | Q13: =Q10-Q12 -> -22.5 | R13: =R10-R12 -> -22.5 | S13: =S10-S12 -> -22.5 | U13: =U10-U12 -> 0 | V13: =V10-V12 -> 0 | W13: =W10-W12 -> 0 | X13: =X10-X12 -> -22.5
A15: Unit Cost | B15: =IFERROR(+B29,0) -> 0 | C15: =IFERROR(+C29,0) -> 0 | D15: =IFERROR(+D29,0) -> 0 | E15: =IFERROR(+E29,0) -> 0 | F15: =IFERROR(+F29,0) -> 0 | G15: =IFERROR(+G29,0) -> 0 | H15: =IFERROR(+H29,0) -> 0 | I15: =IFERROR(+I29,0) -> 0 | ... O15: =IFERROR(+O29,0) -> 0 | Q15: =IFERROR(+Q29,0) -> 0 | R15: =IFERROR(+R29,0) -> 0 | S15: =IFERROR(+S29,0) -> 0 | T15: =IFERROR(+T29,0) -> 0 | U15: =IFERROR(+U29,0) -> 0 | V15: =IFERROR(+V29,0) -> 0 | W15: =IFERROR(+W29,0) -> 0 | X15: =IFERROR(+X29,0) -> 0
A16: Inventory Shortage $$ | B16: =B15*B13 -> 0 | C16: =C15*C13 -> 0 | D16: =D15*D13 -> 0 | E16: =E15*E13 -> 0 | G16: =G15*G13 -> 0 | H16: =H15*H13 -> 0 | I16: =I15*I13 -> 0 | J16: =J15*J13 -> 0 | L16: =L15*L13 -> 0 | M16: =M15*M13 -> 0 | N16: =N15*N13 -> 0 | O16: =O15*O13 -> 0 | Q16: =Q15*Q13 -> 0 | R16: =R15*R13 -> 0 | S16: =S15*S13 -> 0 | U16: =U15*U13 -> 0 | V16: =V15*V13 -> 0 | W16: =W15*W13 -> 0 | X16: =X15*X13 -> 0
A18: Starting Inventory
A19: Purchases | B19: =+'Purchase Log'!C10 -> 0 | C19: =+'Purchase Log'!D10 -> 0 | D19: =+'Purchase Log'!E10 -> 0 | E19: =+'Purchase Log'!F10 -> 0 | G19: =+'Purchase Log'!H10 -> 0 | H19: =+'Purchase Log'!I10 -> 0 | I19: =+'Purchase Log'!J10 -> 0 | J19: =+'Purchase Log'!K10 -> 0 | L19: =+'Purchase Log'!M10 -> 0 | M19: =+'Purchase Log'!N10 -> 0 | N19: =+'Purchase Log'!O10 -> 0 | O19: =+'Purchase Log'!P10 -> 0 | Q19: =+'Purchase Log'!R10 -> 0 | R19: =+'Purchase Log'!S10 -> 0 | S19: =+'Purchase Log'!S10 -> 0 | U19: =+'Purchase Log'!U10 -> 0 | V19: =+'Purchase Log'!V10 -> 0 | W19: =+'Purchase Log'!X10 -> 0 | X19: =+'Purchase Log'!Y10 -> 0
A20: Ending Inventory | B20: =B10 -> 0 | C20: =C10 -> 0 | D20: =D10 -> 0 | E20: =E10 -> 0 | G20: =G10 -> 0 | H20: =H10 -> 0 | I20: =I10 -> 0 | J20: =J10 -> 0 | L20: =L10 -> 15 | M20: =M10 -> 15 | N20: =N10 -> 15 | O20: =O10 -> 0 | Q20: =Q10 -> 15 | R20: =R10 -> 15 | S20: =S10 -> 15 | U20: =U10 -> 0 | V20: =V10 -> 0 | W20: =W10 -> 0 | X20: =X10 -> 15
A21: Usage/Loss Qty | B21: =B18+B19-B20 -> 0 | C21: =C18+C19-C20 -> 0 | D21: =D18+D19-D20 -> 0 | E21: =E18+E19-E20 -> 0 | G21: =G18+G19-G20 -> 0 | H21: =H18+H19-H20 -> 0 | I21: =I18+I19-I20 -> 0 | J21: =J18+J19-J20 -> 0 | L21: =L18+L19-L20 -> -15 | M21: =M18+M19-M20 -> -15 | N21: =N18+N19-N20 -> -15 | O21: =O18+O19-O20 -> 0 | Q21: =Q18+Q19-Q20 -> -15 | R21: =R18+R19-R20 -> -15 | S21: =S18+S19-S20 -> -15 | U21: =U18+U19-U20 -> 0 | V21: =V18+V19-V20 -> 0 | W21: =W18+W19-W20 -> 0 | X21: =X18+X19-X20 -> -15
A22: Loss $$$$$ | B22: =+B21*B15 -> 0 | C22: =+C21*C15 -> 0 | D22: =+D21*D15 -> 0 | E22: =+E21*E15 -> 0 | G22: =+G21*G15 -> 0 | H22: =+H21*H15 -> 0 | I22: =+I21*I15 -> 0 | J22: =+J21*J15 -> 0 | K22: =+K21*K15 -> 0 | L22: =+L21*L15 -> 0 | M22: =+M21*M15 -> 0 | N22: =+N21*N15 -> 0 | O22: =+O21*O15 -> 0 | Q22: =+Q21*Q15 -> 0 | R22: =+R21*R15 -> 0 | S22: =+S21*S15 -> 0 | T22: =+T21*T15 -> 0 | U22: =+U21*U15 -> 0 | V22: =+V21*V15 -> 0 | W22: =+W21*W15 -> 0 | X22: =+X21*X15 -> 0
A23: Monthly Loss Total | B23: =+SUMIF(B22:X22,">0") -> 0 | D23: not including negativer values | H23: =+COUNTIF(B22:X22,"<0") -> 0
B25: Unit Cost Calculator (complete in Q1 only, unit cost values will pull from this sheet for other quarters)
A26: Case Qty | B26: 180 | C26: 120 | D26: 60 | E26: 60 | G26: 24 | H26: 24 | I26: 4 | J26: 1 | L26: 24 | M26: 24 | N26: 4 | O26: 1 | Q26: 24 | R26: 24 | S26: 24 | U26: 72 | V26: 72 | W26: 72 | X26: 72
A27: Case cost
A28: Cs cost w/ tax | B28: =+B27*1.085 -> 0 | C28: =+C27*1.085 -> 0 | D28: =+D27*1.085 -> 0 | E28: =+E27*1.085 -> 0 | G28: =+G27*1.085 -> 0 | H28: =+H27*1.085 -> 0 | I28: =+I27*1.085 -> 0 | J28: =+J27*1.085 -> 0 | L28: =+L27*1.085 -> 0 | M28: =+M27*1.085 -> 0 | N28: =+N27*1.085 -> 0 | O28: =+O27*1.085 -> 0 | Q28: =+Q27*1.085 -> 0 | R28: =+R27*1.085 -> 0 | S28: =+S27*1.085 -> 0 | U28: =+U27*1.085 -> 0 | V28: =+V27*1.085 -> 0 | W28: =+W27*1.085 -> 0 | X28: =+X27*1.085 -> 0
A29: Unit Cost | B29: =+B28/B26 -> 0 | C29: =IFERROR(+C28/C26,0) -> 0 | D29: =IFERROR(+D28/D26,0) -> 0 | E29: =IFERROR(+E28/E26,0) -> 0 | F29: =IFERROR(+F28/F26,0) -> 0 | G29: =IFERROR(+G28/G26,0) -> 0 | H29: =IFERROR(+H28/H26,0) -> 0 | I29: =IFERROR(+I28/I26,0) -> 0 | J29: =IFERROR(+J28/J26,0) -> 0 | ... O29: =IFERROR(+O28/O26,0) -> 0 | Q29: =IFERROR(+Q28/Q26,0) -> 0 | R29: =IFERROR(+R28/R26,0) -> 0 | S29: =IFERROR(+S28/S26,0) -> 0 | T29: =IFERROR(+T28/T26,0) -> 0 | U29: =IFERROR(+U28/U26,0) -> 0 | V29: =IFERROR(+V28/V26,0) -> 0 | W29: =IFERROR(+W28/W26,0) -> 0 | X29: =IFERROR(+X28/X26,0) -> 0

Sheet Total Linen June 30th
A1: =+'Hotel Set up'!B2 -> Enter Property Name and other Details in the Hotel Setup Tab
B3: 2nd Quarter
B4: Bath Linen | G4: Kings | L4: Queens | P4: Full / Sofa Sleepers | T4: Pillowcases
B5: =+'Total Linen March 31st'!B5 -> Wash Cloths | C5: =+'Total Linen March 31st'!C5 -> Hand Towels | D5: =+'Total Linen March 31st'!D5 -> Bath Towels | E5: =+'Total Linen March 31st'!E5 -> Bath Mats | G5: =+'Total Linen March 31st'!G5 -> Flat Sheets | H5: =+'Total Linen March 31st'!H5 -> Fitted Sheets | I5: =+'Total Linen March 31st'!I5 -> Duvets / Comforters | J5: =+'Total Linen March 31st'!J5 -> Duvet Cover / Top Spread | K5: =+'Total Linen March 31st'!K5 -> 0 | L5: =+'Total Linen March 31st'!L5 -> Flat Sheets | M5: =+'Total Linen March 31st'!M5 -> Fitted Sheet | N5: =+'Total Linen March 31st'!N5 -> Duvets / Comforters | O5: =+'Total Linen March 31st'!O5 -> Duvet Cover / Top Spread | P5: =+'Total Linen March 31st'!Q5 -> Blanket / Throw | Q5: =+'Total Linen March 31st'!R5 -> Flat Sheets | R5: =+'Total Linen March 31st'!S5 -> Fitted Sheets | S5: =+'Total Linen March 31st'!T5 -> 0 | T5: King Firm | U5: King Soft | V5: Queen Firm | W5: Queen Soft
A7: In Room PAR | B7: =+'Total Linen March 31st'!B7 -> 0 | C7: =+'Total Linen March 31st'!C7 -> 0 | D7: =+'Total Linen March 31st'!D7 -> 0 | E7: =+'Total Linen March 31st'!E7 -> 0 | G7: =+'Total Linen March 31st'!G7 -> 0 | H7: =+'Total Linen March 31st'!H7 -> 0 | I7: =+'Total Linen March 31st'!I7 -> 0 | J7: =+'Total Linen March 31st'!J7 -> 0 | L7: =+'Total Linen March 31st'!L7 -> 15 | M7: =+'Total Linen March 31st'!M7 -> 15 | N7: =+'Total Linen March 31st'!N7 -> 15 | O7: =+'Total Linen March 31st'!O7 -> 0 | P7: =+'Total Linen March 31st'!Q7 -> 15 | Q7: =+'Total Linen March 31st'!R7 -> 15 | R7: =+'Total Linen March 31st'!S7 -> 15 | T7: =+'Total Linen March 31st'!U7 -> 0 | U7: =+'Total Linen March 31st'!V7 -> 0 | V7: =+'Total Linen March 31st'!W7 -> 0 | W7: =+'Total Linen March 31st'!X7 -> 15
A8: =+'Total Linen March 31st'!A8 -> From Storage Count
A10: Inventory Total | B10: =SUM(B7:B8) -> 0 | C10: =SUM(C7:C8) -> 0 | D10: =SUM(D7:D8) -> 0 | E10: =SUM(E7:E8) -> 0 | G10: =SUM(G7:G8) -> 0 | H10: =SUM(H7:H8) -> 0 | I10: =SUM(I7:I8) -> 0 | J10: =SUM(J7:J8) -> 0 | L10: =SUM(L7:L8) -> 15 | M10: =SUM(M7:M8) -> 15 | N10: =SUM(N7:N8) -> 15 | O10: =SUM(O7:O8) -> 0 | P10: =SUM(P7:P8) -> 15 | Q10: =SUM(Q7:Q8) -> 15 | R10: =SUM(R7:R8) -> 15 | T10: =SUM(T7:T8) -> 0 | U10: =SUM(U7:U8) -> 0 | V10: =SUM(V7:V8) -> 0 | W10: =SUM(W7:W8) -> 15
A12: Par Level | B12: =+B7*2.5 -> 0 | C12: =+C7*2.5 -> 0 | D12: =+D7*2.5 -> 0 | E12: =+E7*2.5 -> 0 | G12: =+G7*2.5 -> 0 | H12: =+H7*2.5 -> 0 | I12: =+I7*2.5 -> 0 | J12: =+J7*2.5 -> 0 | L12: =+(('Hotel Set up'!D19*2)*'Hotel Set up'!F9)+'Hotel Set up'!J19 -> 15 | M12: =+('Hotel Set up'!$D$19*2*'Hotel Set up'!$F$9)+'Hotel Set up'!$J$19 -> 15 | N12: =+N7*2.5 -> 37.5 | O12: =+O7*2.5 -> 0 | P12: =+P7*2.5 -> 37.5 | Q12: =+Q7*2.5 -> 37.5 | R12: =+R7*2.5 -> 37.5 | T12: =+T7*2.5 -> 0 | U12: =+U7*2.5 -> 0 | V12: =+V7*2.5 -> 0 | W12: =+W7*2.5 -> 37.5
A13: Inventory Variance | B13: =B10-B12 -> 0 | C13: =C10-C12 -> 0 | D13: =D10-D12 -> 0 | E13: =E10-E12 -> 0 | G13: =G10-G12 -> 0 | H13: =H10-H12 -> 0 | I13: =I10-I12 -> 0 | J13: =J10-J12 -> 0 | L13: =L10-L12 -> 0 | M13: =M10-M12 -> 0 | N13: =N10-N12 -> -22.5 | O13: =O10-O12 -> 0 | P13: =P10-P12 -> -22.5 | Q13: =Q10-Q12 -> -22.5 | R13: =R10-R12 -> -22.5 | T13: =T10-T12 -> 0 | U13: =U10-U12 -> 0 | V13: =V10-V12 -> 0 | W13: =W10-W12 -> -22.5
A15: Unit Cost | B15: =+'Total Linen March 31st'!B15 -> 0 | C15: =+'Total Linen March 31st'!C15 -> 0 | D15: =+'Total Linen March 31st'!D15 -> 0 | E15: =+'Total Linen March 31st'!E15 -> 0 | F15: =+'Total Linen March 31st'!F15 -> 0 | G15: =+'Total Linen March 31st'!G15 -> 0 | H15: =+'Total Linen March 31st'!H15 -> 0 | I15: =+'Total Linen March 31st'!I15 -> 0 | ... O15: =+'Total Linen March 31st'!O15 -> 0 | P15: =+'Total Linen March 31st'!Q15 -> 0 | Q15: =+'Total Linen March 31st'!R15 -> 0 | R15: =+'Total Linen March 31st'!S15 -> 0 | S15: =+'Total Linen March 31st'!T15 -> 0 | T15: =+'Total Linen March 31st'!U15 -> 0 | U15: =+'Total Linen March 31st'!V15 -> 0 | V15: =+'Total Linen March 31st'!W15 -> 0 | W15: =+'Total Linen March 31st'!X15 -> 0
A16: Inventory Shortage $$ | B16: =B15*B13 -> 0 | C16: =C15*C13 -> 0 | D16: =D15*D13 -> 0 | E16: =E15*E13 -> 0 | G16: =G15*G13 -> 0 | H16: =H15*H13 -> 0 | I16: =I15*I13 -> 0 | J16: =J15*J13 -> 0 | L16: =L15*L13 -> 0 | M16: =M15*M13 -> 0 | N16: =N15*N13 -> 0 | O16: =O15*O13 -> 0 | P16: =P15*P13 -> 0 | Q16: =Q15*Q13 -> 0 | R16: =R15*R13 -> 0 | T16: =T15*T13 -> 0 | U16: =U15*U13 -> 0 | V16: =V15*V13 -> 0 | W16: =W15*W13 -> 0
A18: Starting Inventory | B18: =+'Total Linen March 31st'!B10 -> 0 | C18: =+'Total Linen March 31st'!C10 -> 0 | D18: =+'Total Linen March 31st'!D10 -> 0 | E18: =+'Total Linen March 31st'!E10 -> 0 | F18: =+'Total Linen March 31st'!F10 -> 0 | G18: =+'Total Linen March 31st'!G10 -> 0 | H18: =+'Total Linen March 31st'!H10 -> 0 | I18: =+'Total Linen March 31st'!I10 -> 0 | ... O18: =+'Total Linen March 31st'!O10 -> 0 | P18: =+'Total Linen March 31st'!Q10 -> 15 | Q18: =+'Total Linen March 31st'!R10 -> 15 | R18: =+'Total Linen March 31st'!S10 -> 15 | S18: =+'Total Linen March 31st'!T10 -> 0 | T18: =+'Total Linen March 31st'!U10 -> 0 | U18: =+'Total Linen March 31st'!V10 -> 0 | V18: =+'Total Linen March 31st'!W10 -> 0 | W18: =+'Total Linen March 31st'!X10 -> 15
A19: Purchases | B19: =+'Purchase Log'!C16 -> 0 | C19: =+'Purchase Log'!D16 -> 0 | D19: =+'Purchase Log'!E16 -> 0 | E19: =+'Purchase Log'!F16 -> 0 | F19: =+'Purchase Log'!G16 -> 0 | G19: =+'Purchase Log'!H16 -> 0 | H19: =+'Purchase Log'!I16 -> 0 | I19: =+'Purchase Log'!J16 -> 0 | ... O19: =+'Purchase Log'!P16 -> 0 | P19: =+'Purchase Log'!R16 -> 0 | Q19: =+'Purchase Log'!S16 -> 0 | R19: =+'Purchase Log'!S16 -> 0 | S19: =+'Purchase Log'!U16 -> 0 | T19: =+'Purchase Log'!V16 -> 0 | U19: =+'Purchase Log'!W16 -> 0 | V19: =+'Purchase Log'!X16 -> 0 | W19: =+'Purchase Log'!Y16 -> 0
A20: Ending Inventory | B20: =B10 -> 0 | C20: =C10 -> 0 | D20: =D10 -> 0 | E20: =E10 -> 0 | G20: =G10 -> 0 | H20: =H10 -> 0 | I20: =I10 -> 0 | J20: =J10 -> 0 | L20: =L10 -> 15 | M20: =M10 -> 15 | N20: =N10 -> 15 | O20: =O10 -> 0 | P20: =P10 -> 15 | Q20: =Q10 -> 15 | R20: =R10 -> 15 | T20: =T10 -> 0 | U20: =U10 -> 0 | V20: =V10 -> 0 | W20: =W10 -> 15
A21: Usage/Loss Qty | B21: =B18+B19-B20 -> 0 | C21: =C18+C19-C20 -> 0 | D21: =D18+D19-D20 -> 0 | E21: =E18+E19-E20 -> 0 | G21: =G18+G19-G20 -> 0 | H21: =H18+H19-H20 -> 0 | I21: =I18+I19-I20 -> 0 | J21: =J18+J19-J20 -> 0 | L21: =L18+L19-L20 -> 0 | M21: =M18+M19-M20 -> 0 | N21: =N18+N19-N20 -> 0 | O21: =O18+O19-O20 -> 0 | P21: =P18+P19-P20 -> 0 | Q21: =Q18+Q19-Q20 -> 0 | R21: =R18+R19-R20 -> 0 | T21: =T18+T19-T20 -> 0 | U21: =U18+U19-U20 -> 0 | V21: =V18+V19-V20 -> 0 | W21: =W18+W19-W20 -> 0
A22: Loss $$$$$ | B22: =+B21*B15 -> 0 | C22: =+C21*C15 -> 0 | D22: =+D21*D15 -> 0 | E22: =+E21*E15 -> 0 | G22: =+G21*G15 -> 0 | H22: =+H21*H15 -> 0 | I22: =+I21*I15 -> 0 | J22: =+J21*J15 -> 0 | K22: =+K21*K15 -> 0 | L22: =+L21*L15 -> 0 | M22: =+M21*M15 -> 0 | N22: =+N21*N15 -> 0 | ... W22: =+W21*W15 -> 0
A23: Monthly Loss Total | B23: =+SUMIF(B22:W22,">0") -> 0 | D23: not including negative values | H23: =+COUNTIF(B22:W22,"<0") -> 0

Sheet Total Linen Sept 30th
A1: =+'Hotel Set up'!B2 -> Enter Property Name and other Details in the Hotel Setup Tab
B3: 3rd Quarter
B4: Bath Linen | G4: Kings | L4: Queens | Q4: Full / Sofa Sleepers | U4: Pillowcases
B5: =+'Total Linen March 31st'!B5 -> Wash Cloths | C5: =+'Total Linen March 31st'!C5 -> Hand Towels | D5: =+'Total Linen March 31st'!D5 -> Bath Towels | E5: =+'Total Linen March 31st'!E5 -> Bath Mats | F5: =+'Total Linen March 31st'!F5 -> 0 | G5: =+'Total Linen March 31st'!G5 -> Flat Sheets | H5: =+'Total Linen March 31st'!H5 -> Fitted Sheets | I5: =+'Total Linen March 31st'!I5 -> Duvets / Comforters | ... T5: =+'Total Linen March 31st'!T5 -> 0 | U5: King Firm | V5: King Soft | W5: Queen Firm | X5: Queen Soft
A7: In Room PAR | B7: =+'Total Linen March 31st'!B7 -> 0 | C7: =+'Total Linen March 31st'!C7 -> 0 | D7: =+'Total Linen March 31st'!D7 -> 0 | E7: =+'Total Linen March 31st'!E7 -> 0 | G7: =+'Total Linen March 31st'!G7 -> 0 | H7: =+'Total Linen March 31st'!H7 -> 0 | I7: =+'Total Linen March 31st'!I7 -> 0 | J7: =+'Total Linen March 31st'!J7 -> 0 | L7: =+'Total Linen March 31st'!L7 -> 15 | M7: =+'Total Linen March 31st'!M7 -> 15 | N7: =+'Total Linen March 31st'!N7 -> 15 | O7: =+'Total Linen March 31st'!O7 -> 0 | Q7: =+'Total Linen March 31st'!Q7 -> 15 | R7: =+'Total Linen March 31st'!R7 -> 15 | S7: =+'Total Linen March 31st'!S7 -> 15 | U7: =+'Total Linen March 31st'!U7 -> 0 | V7: =+'Total Linen March 31st'!V7 -> 0 | W7: =+'Total Linen March 31st'!W7 -> 0 | X7: =+'Total Linen March 31st'!X7 -> 15
A8: =+'Total Linen March 31st'!A8 -> From Storage Count
A10: Inventory Total | B10: =SUM(B7:B8) -> 0 | C10: =SUM(C7:C8) -> 0 | D10: =SUM(D7:D8) -> 0 | E10: =SUM(E7:E8) -> 0 | G10: =SUM(G7:G8) -> 0 | H10: =SUM(H7:H8) -> 0 | I10: =SUM(I7:I8) -> 0 | J10: =SUM(J7:J8) -> 0 | L10: =SUM(L7:L8) -> 15 | M10: =SUM(M7:M8) -> 15 | N10: =SUM(N7:N8) -> 15 | O10: =SUM(O7:O8) -> 0 | Q10: =SUM(Q7:Q8) -> 15 | R10: =SUM(R7:R8) -> 15 | S10: =SUM(S7:S8) -> 15 | U10: =SUM(U7:U8) -> 0 | V10: =SUM(V7:V8) -> 0 | W10: =SUM(W7:W8) -> 0 | X10: =SUM(X7:X8) -> 15
A12: Par Level | B12: =+B7*2.5 -> 0 | C12: =+C7*2.5 -> 0 | D12: =+D7*2.5 -> 0 | E12: =+E7*2.5 -> 0 | G12: =+G7*2.5 -> 0 | H12: =+H7*2.5 -> 0 | I12: =+I7*2.5 -> 0 | J12: =+J7*2.5 -> 0 | L12: =+(('Hotel Set up'!D19*2)*'Hotel Set up'!F9)+'Hotel Set up'!J19 -> 15 | M12: =+('Hotel Set up'!$D$19*2*'Hotel Set up'!$F$9)+'Hotel Set up'!$J$19 -> 15 | N12: =+N7*2.5 -> 37.5 | O12: =+O7*2.5 -> 0 | Q12: =+Q7*2.5 -> 37.5 | R12: =+R7*2.5 -> 37.5 | S12: =+S7*2.5 -> 37.5 | U12: =+U7*2.5 -> 0 | V12: =+V7*2.5 -> 0 | W12: =+W7*2.5 -> 0 | X12: =+X7*2.5 -> 37.5
A13: Inventory Variance | B13: =B10-B12 -> 0 | C13: =C10-C12 -> 0 | D13: =D10-D12 -> 0 | E13: =E10-E12 -> 0 | G13: =G10-G12 -> 0 | H13: =H10-H12 -> 0 | I13: =I10-I12 -> 0 | J13: =J10-J12 -> 0 | L13: =L10-L12 -> 0 | M13: =M10-M12 -> 0 | N13: =N10-N12 -> -22.5 | O13: =O10-O12 -> 0 | Q13: =Q10-Q12 -> -22.5 | R13: =R10-R12 -> -22.5 | S13: =S10-S12 -> -22.5 | U13: =U10-U12 -> 0 | V13: =V10-V12 -> 0 | W13: =W10-W12 -> 0 | X13: =X10-X12 -> -22.5
A15: Unit Cost | B15: =+'Total Linen June 30th'!B15 -> 0 | C15: =+'Total Linen June 30th'!C15 -> 0 | D15: =+'Total Linen June 30th'!D15 -> 0 | E15: =+'Total Linen June 30th'!E15 -> 0 | F15: =+'Total Linen June 30th'!F15 -> 0 | G15: =+'Total Linen June 30th'!G15 -> 0 | H15: =+'Total Linen June 30th'!H15 -> 0 | I15: =+'Total Linen June 30th'!I15 -> 0 | ... O15: =+'Total Linen June 30th'!O15 -> 0 | P15: =+'Total Linen June 30th'!#REF! -> #REF! | Q15: =+'Total Linen June 30th'!P15 -> 0 | R15: =+'Total Linen June 30th'!Q15 -> 0 | S15: =+'Total Linen June 30th'!R15 -> 0 | T15: =+'Total Linen June 30th'!S15 -> 0 | U15: =+'Total Linen June 30th'!T15 -> 0 | V15: =+'Total Linen June 30th'!U15 -> 0 | W15: =+'Total Linen June 30th'!V15 -> 0 | X15: =+'Total Linen June 30th'!W15 -> 0
A16: Inventory Shortage $$ | B16: =B15*B13 -> 0 | C16: =C15*C13 -> 0 | D16: =D15*D13 -> 0 | E16: =E15*E13 -> 0 | G16: =G15*G13 -> 0 | H16: =H15*H13 -> 0 | I16: =I15*I13 -> 0 | J16: =J15*J13 -> 0 | L16: =L15*L13 -> 0 | M16: =M15*M13 -> 0 | N16: =N15*N13 -> 0 | O16: =O15*O13 -> 0 | Q16: =Q15*Q13 -> 0 | R16: =R15*R13 -> 0 | S16: =S15*S13 -> 0 | U16: =U15*U13 -> 0 | V16: =V15*V13 -> 0 | W16: =W15*W13 -> 0 | X16: =X15*X13 -> 0
A18: Starting Inventory | B18: =+'Total Linen June 30th'!B10 -> 0 | C18: =+'Total Linen June 30th'!C10 -> 0 | D18: =+'Total Linen June 30th'!D10 -> 0 | E18: =+'Total Linen June 30th'!E10 -> 0 | F18: =+'Total Linen June 30th'!F10 -> 0 | G18: =+'Total Linen June 30th'!G10 -> 0 | H18: =+'Total Linen June 30th'!H10 -> 0 | I18: =+'Total Linen June 30th'!I10 -> 0 | ... O18: =+'Total Linen June 30th'!O10 -> 0 | P18: =+'Total Linen June 30th'!#REF! -> #REF! | Q18: =+'Total Linen June 30th'!P10 -> 15 | R18: =+'Total Linen June 30th'!Q10 -> 15 | S18: =+'Total Linen June 30th'!R10 -> 15 | T18: =+'Total Linen June 30th'!S10 -> 0 | U18: =+'Total Linen June 30th'!T10 -> 0 | V18: =+'Total Linen June 30th'!U10 -> 0 | W18: =+'Total Linen June 30th'!V10 -> 0 | X18: =+'Total Linen June 30th'!W10 -> 15
A19: Purchases | B19: =+'Purchase Log'!C10 -> 0 | C19: =+'Purchase Log'!D10 -> 0 | D19: =+'Purchase Log'!E10 -> 0 | E19: =+'Purchase Log'!F10 -> 0 | G19: =+'Purchase Log'!H10 -> 0 | H19: =+'Purchase Log'!I10 -> 0 | I19: =+'Purchase Log'!J10 -> 0 | J19: =+'Purchase Log'!K10 -> 0 | L19: =+'Purchase Log'!M10 -> 0 | M19: =+'Purchase Log'!N10 -> 0 | N19: =+'Purchase Log'!O10 -> 0 | O19: =+'Purchase Log'!P10 -> 0 | Q19: =+'Purchase Log'!R10 -> 0 | R19: =+'Purchase Log'!S10 -> 0 | S19: =+'Purchase Log'!S10 -> 0 | U19: =+'Purchase Log'!V10 -> 0 | V19: =+'Purchase Log'!W10 -> 0 | W19: =+'Purchase Log'!X10 -> 0 | X19: =+'Purchase Log'!Y10 -> 0
A20: Ending Inventory | B20: =B10 -> 0 | C20: =C10 -> 0 | D20: =D10 -> 0 | E20: =E10 -> 0 | G20: =G10 -> 0 | H20: =H10 -> 0 | I20: =I10 -> 0 | J20: =J10 -> 0 | L20: =L10 -> 15 | M20: =M10 -> 15 | N20: =N10 -> 15 | O20: =O10 -> 0 | Q20: =Q10 -> 15 | R20: =R10 -> 15 | S20: =S10 -> 15 | U20: =U10 -> 0 | V20: =V10 -> 0 | W20: =W10 -> 0 | X20: =X10 -> 15
A21: Usage/Loss Qty | B21: =B18+B19-B20 -> 0 | C21: =C18+C19-C20 -> 0 | D21: =D18+D19-D20 -> 0 | E21: =E18+E19-E20 -> 0 | G21: =G18+G19-G20 -> 0 | H21: =H18+H19-H20 -> 0 | I21: =I18+I19-I20 -> 0 | J21: =J18+J19-J20 -> 0 | L21: =L18+L19-L20 -> 0 | M21: =M18+M19-M20 -> 0 | N21: =N18+N19-N20 -> 0 | O21: =O18+O19-O20 -> 0 | Q21: =Q18+Q19-Q20 -> 0 | R21: =R18+R19-R20 -> 0 | S21: =S18+S19-S20 -> 0 | U21: =U18+U19-U20 -> 0 | V21: =V18+V19-V20 -> 0 | W21: =W18+W19-W20 -> 0 | X21: =X18+X19-X20 -> 0
A22: Loss $$$$$ | B22: =+B21*B15 -> 0 | C22: =+C21*C15 -> 0 | D22: =+D21*D15 -> 0 | E22: =+E21*E15 -> 0 | G22: =+G21*G15 -> 0 | H22: =+H21*H15 -> 0 | I22: =+I21*I15 -> 0 | J22: =+J21*J15 -> 0 | K22: =+K21*K15 -> 0 | L22: =+L21*L15 -> 0 | M22: =+M21*M15 -> 0 | N22: =+N21*N15 -> 0 | ... X22: =+X21*X15 -> 0
A23: Monthly Loss Total | B23: =+SUMIF(B22:X22,">0") -> 0 | D23: not including negative values | H23: =+COUNTIF(B22:X22,"<0") -> 0

Sheet Total Linen Dec 31st
A1: =+'Hotel Set up'!B2 -> Enter Property Name and other Details in the Hotel Setup Tab
B3: 4th Quarter
B4: Bath Linen | G4: Kings | L4: Queens | Q4: Full / Sofa Sleepers | U4: Pillowcases
B5: =+'Total Linen March 31st'!B5 -> Wash Cloths | C5: =+'Total Linen March 31st'!C5 -> Hand Towels | D5: =+'Total Linen March 31st'!D5 -> Bath Towels | E5: =+'Total Linen March 31st'!E5 -> Bath Mats | F5: =+'Total Linen March 31st'!F5 -> 0 | G5: =+'Total Linen March 31st'!G5 -> Flat Sheets | H5: =+'Total Linen March 31st'!H5 -> Fitted Sheets | I5: =+'Total Linen March 31st'!I5 -> Duvets / Comforters | ... T5: =+'Total Linen March 31st'!T5 -> 0 | U5: King Firm | V5: King Soft | W5: Queen Firm | X5: Queen Soft
A7: In Room PAR | B7: =+'Total Linen March 31st'!B7 -> 0 | C7: =+'Total Linen March 31st'!C7 -> 0 | D7: =+'Total Linen March 31st'!D7 -> 0 | E7: =+'Total Linen March 31st'!E7 -> 0 | G7: =+'Total Linen March 31st'!G7 -> 0 | H7: =+'Total Linen March 31st'!H7 -> 0 | I7: =+'Total Linen March 31st'!I7 -> 0 | J7: =+'Total Linen March 31st'!J7 -> 0 | L7: =+'Total Linen March 31st'!L7 -> 15 | M7: =+'Total Linen March 31st'!M7 -> 15 | N7: =+'Total Linen March 31st'!N7 -> 15 | O7: =+'Total Linen March 31st'!O7 -> 0 | Q7: =+'Total Linen March 31st'!Q7 -> 15 | R7: =+'Total Linen March 31st'!R7 -> 15 | S7: =+'Total Linen March 31st'!S7 -> 15 | U7: =+'Total Linen March 31st'!U7 -> 0 | V7: =+'Total Linen March 31st'!V7 -> 0 | W7: =+'Total Linen March 31st'!W7 -> 0 | X7: =+'Total Linen March 31st'!X7 -> 15
A8: =+'Total Linen March 31st'!A8 -> From Storage Count
A10: Inventory Total | B10: =SUM(B7:B8) -> 0 | C10: =SUM(C7:C8) -> 0 | D10: =SUM(D7:D8) -> 0 | E10: =SUM(E7:E8) -> 0 | G10: =SUM(G7:G8) -> 0 | H10: =SUM(H7:H8) -> 0 | I10: =SUM(I7:I8) -> 0 | J10: =SUM(J7:J8) -> 0 | L10: =SUM(L7:L8) -> 15 | M10: =SUM(M7:M8) -> 15 | N10: =SUM(N7:N8) -> 15 | O10: =SUM(O7:O8) -> 0 | Q10: =SUM(Q7:Q8) -> 15 | R10: =SUM(R7:R8) -> 15 | S10: =SUM(S7:S8) -> 15 | U10: =SUM(U7:U8) -> 0 | V10: =SUM(V7:V8) -> 0 | W10: =SUM(W7:W8) -> 0 | X10: =SUM(X7:X8) -> 15
A12: Par Level | B12: =+B7*2.5 -> 0 | C12: =+C7*2.5 -> 0 | D12: =+D7*2.5 -> 0 | E12: =+E7*2.5 -> 0 | G12: =+G7*2.5 -> 0 | H12: =+H7*2.5 -> 0 | I12: =+I7*2.5 -> 0 | J12: =+J7*2.5 -> 0 | L12: =+(('Hotel Set up'!D19*2)*'Hotel Set up'!F9)+'Hotel Set up'!J19 -> 15 | M12: =+('Hotel Set up'!$D$19*2*'Hotel Set up'!$F$9)+'Hotel Set up'!$J$19 -> 15 | N12: =+N7*2.5 -> 37.5 | O12: =+O7*2.5 -> 0 | Q12: =+Q7*2.5 -> 37.5 | R12: =+R7*2.5 -> 37.5 | S12: =+S7*2.5 -> 37.5 | U12: =+U7*2.5 -> 0 | V12: =+V7*2.5 -> 0 | W12: =+W7*2.5 -> 0 | X12: =+X7*2.5 -> 37.5
A13: Inventory Variance | B13: =B10-B12 -> 0 | C13: =C10-C12 -> 0 | D13: =D10-D12 -> 0 | E13: =E10-E12 -> 0 | G13: =G10-G12 -> 0 | H13: =H10-H12 -> 0 | I13: =I10-I12 -> 0 | J13: =J10-J12 -> 0 | L13: =L10-L12 -> 0 | M13: =M10-M12 -> 0 | N13: =N10-N12 -> -22.5 | O13: =O10-O12 -> 0 | Q13: =Q10-Q12 -> -22.5 | R13: =R10-R12 -> -22.5 | S13: =S10-S12 -> -22.5 | U13: =U10-U12 -> 0 | V13: =V10-V12 -> 0 | W13: =W10-W12 -> 0 | X13: =X10-X12 -> -22.5
A15: Unit Cost | B15: =+'Total Linen Sept 30th'!B15 -> 0 | C15: =+'Total Linen Sept 30th'!C15 -> 0 | D15: =+'Total Linen Sept 30th'!D15 -> 0 | E15: =+'Total Linen Sept 30th'!E15 -> 0 | F15: =+'Total Linen Sept 30th'!F15 -> 0 | G15: =+'Total Linen Sept 30th'!G15 -> 0 | H15: =+'Total Linen Sept 30th'!H15 -> 0 | I15: =+'Total Linen Sept 30th'!I15 -> 0 | ... X15: =+'Total Linen Sept 30th'!X15 -> 0
A16: Inventory Shortage $$ | B16: =B15*B13 -> 0 | C16: =C15*C13 -> 0 | D16: =D15*D13 -> 0 | E16: =E15*E13 -> 0 | G16: =G15*G13 -> 0 | H16: =H15*H13 -> 0 | I16: =I15*I13 -> 0 | J16: =J15*J13 -> 0 | L16: =L15*L13 -> 0 | M16: =M15*M13 -> 0 | N16: =N15*N13 -> 0 | O16: =O15*O13 -> 0 | Q16: =Q15*Q13 -> 0 | R16: =R15*R13 -> 0 | S16: =S15*S13 -> 0 | U16: =U15*U13 -> 0 | V16: =V15*V13 -> 0 | W16: =W15*W13 -> 0 | X16: =X15*X13 -> 0
A18: Starting Inventory | B18: =+'Total Linen Sept 30th'!B10 -> 0 | C18: =+'Total Linen Sept 30th'!C10 -> 0 | D18: =+'Total Linen Sept 30th'!D10 -> 0 | E18: =+'Total Linen Sept 30th'!E10 -> 0 | F18: =+'Total Linen Sept 30th'!F10 -> 0 | G18: =+'Total Linen Sept 30th'!G10 -> 0 | H18: =+'Total Linen Sept 30th'!H10 -> 0 | I18: =+'Total Linen Sept 30th'!I10 -> 0 | ... X18: =+'Total Linen Sept 30th'!X10 -> 15
A19: Purchases | B19: =+'Purchase Log'!C10 -> 0 | C19: =+'Purchase Log'!D10 -> 0 | D19: =+'Purchase Log'!E10 -> 0 | E19: =+'Purchase Log'!F10 -> 0 | G19: =+'Purchase Log'!H10 -> 0 | H19: =+'Purchase Log'!I10 -> 0 | I19: =+'Purchase Log'!J10 -> 0 | J19: =+'Purchase Log'!K10 -> 0 | L19: =+'Purchase Log'!M10 -> 0 | M19: =+'Purchase Log'!N10 -> 0 | N19: =+'Purchase Log'!O10 -> 0 | O19: =+'Purchase Log'!P10 -> 0 | Q19: =+'Purchase Log'!R10 -> 0 | R19: =+'Purchase Log'!S10 -> 0 | S19: =+'Purchase Log'!S10 -> 0 | U19: =+'Purchase Log'!V10 -> 0 | V19: =+'Purchase Log'!W10 -> 0 | W19: =+'Purchase Log'!X10 -> 0 | X19: =+'Purchase Log'!Y10 -> 0
A20: Ending Inventory | B20: =B10 -> 0 | C20: =C10 -> 0 | D20: =D10 -> 0 | E20: =E10 -> 0 | G20: =G10 -> 0 | H20: =H10 -> 0 | I20: =I10 -> 0 | J20: =J10 -> 0 | L20: =L10 -> 15 | M20: =M10 -> 15 | N20: =N10 -> 15 | O20: =O10 -> 0 | Q20: =Q10 -> 15 | R20: =R10 -> 15 | S20: =S10 -> 15 | U20: =U10 -> 0 | V20: =V10 -> 0 | W20: =W10 -> 0 | X20: =X10 -> 15
A21: Usage/Loss Qty | B21: =B18+B19-B20 -> 0 | C21: =C18+C19-C20 -> 0 | D21: =D18+D19-D20 -> 0 | E21: =E18+E19-E20 -> 0 | G21: =G18+G19-G20 -> 0 | H21: =H18+H19-H20 -> 0 | I21: =I18+I19-I20 -> 0 | J21: =J18+J19-J20 -> 0 | L21: =L18+L19-L20 -> 0 | M21: =M18+M19-M20 -> 0 | N21: =N18+N19-N20 -> 0 | O21: =O18+O19-O20 -> 0 | Q21: =Q18+Q19-Q20 -> 0 | R21: =R18+R19-R20 -> 0 | S21: =S18+S19-S20 -> 0 | U21: =U18+U19-U20 -> 0 | V21: =V18+V19-V20 -> 0 | W21: =W18+W19-W20 -> 0 | X21: =X18+X19-X20 -> 0
A22: Loss $$$$$ | B22: =+B21*B15 -> 0 | C22: =+C21*C15 -> 0 | D22: =+D21*D15 -> 0 | E22: =+E21*E15 -> 0 | G22: =+G21*G15 -> 0 | H22: =+H21*H15 -> 0 | I22: =+I21*I15 -> 0 | J22: =+J21*J15 -> 0 | K22: =+K21*K15 -> 0 | L22: =+L21*L15 -> 0 | M22: =+M21*M15 -> 0 | N22: =+N21*N15 -> 0 | ... X22: =+X21*X15 -> 0
A23: Monthly Loss Total | B23: =+SUMIF(B22:X22,">0") -> 0 | D23: not including credit values | G23: =+COUNTIF(B22:X22,"<0") -> 0

Sheet Reports
A1: =+'Hotel Set up'!B2:N3 -> #VALUE!
A2: Current Quarter | D2: 3.1 | G2: You must select the quarter from the drop down box. You may not manually enter the number. | P2: password is | R2: hotel
C3: Par Variance
C4: Quarter
C5: 1 | D5: change | F5: 2 | G5: change | I5: 3 | J5: change | L5: 4 | M5: change
A6: Terry
A7: Wash Cloths | C7: =+IF($C$5<$D$2,+'Total Linen March 31st'!$B$13,0) -> 0 | F7: =+IF($F$5<$D$2,+'Total Linen June 30th'!#REF!,0) -> #REF! | G7: =+F7-C7 -> #REF! | I7: =+IF($I$5<$D$2,+'Total Linen Sept 30th'!#REF!,0) -> #REF! | J7: =+I7-F7 -> #REF! | L7: =+IF($L$5<$D$2,+'Total Linen Dec 31st'!#REF!,0) -> 0 | M7: =+L7-I7 -> #REF! | P7: This report shows our variance from our par level each quarter. The "change" column should show positive numbers for any items that are negativve in the quarterly count column. Positive numbers means that our overall inventory grew closer toward our desired par level. Negative numbers show that we lost ground for that specific item during the quarter. Wise purchasing and reducing loss will produce these positive numbers and allow our inventories to gain ground toward our preferred inventory par levels. Make sure the "current quarter" is accurate in cell D2.
A8: Hand Towels | C8: =+IF($C$5<$D$2,+'Total Linen March 31st'!$C$13,0) -> 0 | F8: =+IF($F$5<$D$2,+'Total Linen June 30th'!#REF!,0) -> #REF! | G8: =+F8-C8 -> #REF! | I8: =+IF($I$5<$D$2,+'Total Linen Sept 30th'!#REF!,0) -> #REF! | J8: =+I8-F8 -> #REF! | L8: =+IF($L$5<$D$2,+'Total Linen Dec 31st'!#REF!,0) -> 0 | M8: =+L8-I8 -> #REF!
A9: Bath Towels | C9: =+IF($C$5<$D$2,+'Total Linen March 31st'!$D$13,0) -> 0 | F9: =+IF($F$5<$D$2,+'Total Linen June 30th'!#REF!,0) -> #REF! | G9: =+F9-C9 -> #REF! | I9: =+IF($I$5<$D$2,+'Total Linen Sept 30th'!#REF!,0) -> #REF! | J9: =+I9-F9 -> #REF! | L9: =+IF($L$5<$D$2,+'Total Linen Dec 31st'!#REF!,0) -> 0 | M9: =+L9-I9 -> #REF!
A10: Bath Mats | C10: =+IF($C$5<$D$2,+'Total Linen March 31st'!$E$13,0) -> 0 | F10: =+IF($F$5<$D$2,+'Total Linen June 30th'!#REF!,0) -> #REF! | G10: =+F10-C10 -> #REF! | I10: =+IF($I$5<$D$2,+'Total Linen Sept 30th'!#REF!,0) -> #REF! | J10: =+I10-F10 -> #REF! | L10: =+IF($L$5<$D$2,+'Total Linen Dec 31st'!#REF!,0) -> 0 | M10: =+L10-I10 -> #REF! | AA10: 1.1
A11: Pool Towels | C11: =+IF($C$5<$D$2,+'Total Linen March 31st'!#REF!,0) -> #REF! | F11: =+IF($F$5<$D$2,+'Total Linen June 30th'!#REF!,0) -> #REF! | G11: =+F11-C11 -> #REF! | I11: =+IF($I$5<$D$2,+'Total Linen Sept 30th'!#REF!,0) -> #REF! | J11: =+I11-F11 -> #REF! | L11: =+IF($L$5<$D$2,+'Total Linen Dec 31st'!#REF!,0) -> 0 | M11: =+L11-I11 -> #REF! | AA11: 2.1
AA12: 3.1
A13: King Linens | AA13: 4.1
A14: Flat Sheets | C14: =+IF($C$5<$D$2,+'Total Linen March 31st'!$G$13,0) -> 0 | F14: =+IF($F$5<$D$2,+'Total Linen June 30th'!#REF!,0) -> #REF! | G14: =+F14-C14 -> #REF! | I14: =+IF($I$5<$D$2,+'Total Linen Sept 30th'!#REF!,0) -> #REF! | J14: =+I14-F14 -> #REF! | L14: =+IF($L$5<$D$2,+'Total Linen Dec 31st'!#REF!,0) -> 0 | M14: =+L14-I14 -> #REF!
A15: Fitted Sheets | C15: =+IF($C$5<$D$2,+'Total Linen March 31st'!$H$13,0) -> 0 | F15: =+IF($F$5<$D$2,+'Total Linen June 30th'!#REF!,0) -> #REF! | G15: =+F15-C15 -> #REF! | I15: =+IF($I$5<$D$2,+'Total Linen Sept 30th'!#REF!,0) -> #REF! | J15: =+I15-F15 -> #REF! | L15: =+IF($L$5<$D$2,+'Total Linen Dec 31st'!#REF!,0) -> 0 | M15: =+L15-I15 -> #REF!
A16: Mattress Pads | C16: =+IF($C$5<$D$2,+'Total Linen March 31st'!#REF!,0) -> #REF! | F16: =+IF($F$5<$D$2,+'Total Linen June 30th'!#REF!,0) -> #REF! | G16: =+F16-C16 -> #REF! | I16: =+IF($I$5<$D$2,+'Total Linen Sept 30th'!#REF!,0) -> #REF! | J16: =+I16-F16 -> #REF! | L16: =+IF($L$5<$D$2,+'Total Linen Dec 31st'!#REF!,0) -> 0 | M16: =+L16-I16 -> #REF!
A17: Blankets | C17: =+IF($C$5<$D$2,+'Total Linen March 31st'!$I$13,0) -> 0 | F17: =+IF($F$5<$D$2,+'Total Linen June 30th'!#REF!,0) -> #REF! | G17: =+F17-C17 -> #REF! | I17: =+IF($I$5<$D$2,+'Total Linen Sept 30th'!#REF!,0) -> #REF! | J17: =+I17-F17 -> #REF! | L17: =+IF($L$5<$D$2,+'Total Linen Dec 31st'!#REF!,0) -> 0 | M17: =+L17-I17 -> #REF!
A18: Duvet's | C18: =+IF($C$5<$D$2,+'Total Linen March 31st'!$J$13,0) -> 0 | F18: =+IF($F$5<$D$2,+'Total Linen June 30th'!#REF!,0) -> #REF! | G18: =+F18-C18 -> #REF! | I18: =+IF($I$5<$D$2,+'Total Linen Sept 30th'!#REF!,0) -> #REF! | J18: =+I18-F18 -> #REF! | L18: =+IF($L$5<$D$2,+'Total Linen Dec 31st'!#REF!,0) -> 0 | M18: =+L18-I18 -> #REF!
A20: Queen Linens
A21: Flat Sheets | C21: =+IF($C$5<$D$2,+'Total Linen March 31st'!$L$13,0) -> 0 | F21: =+IF($F$5<$D$2,+'Total Linen June 30th'!#REF!,0) -> #REF! | G21: =+F21-C21 -> #REF! | I21: =+IF($I$5<$D$2,+'Total Linen Sept 30th'!#REF!,0) -> #REF! | J21: =+I21-F21 -> #REF! | L21: =+IF($L$5<$D$2,+'Total Linen Dec 31st'!#REF!,0) -> 0 | M21: =+L21-I21 -> #REF!
A22: Fitted Sheets | C22: =+IF($C$5<$D$2,+'Total Linen March 31st'!$M$13,0) -> 0 | F22: =+IF($F$5<$D$2,+'Total Linen June 30th'!#REF!,0) -> #REF! | G22: =+F22-C22 -> #REF! | I22: =+IF($I$5<$D$2,+'Total Linen Sept 30th'!#REF!,0) -> #REF! | J22: =+I22-F22 -> #REF! | L22: =+IF($L$5<$D$2,+'Total Linen Dec 31st'!#REF!,0) -> 0 | M22: =+L22-I22 -> #REF!
A23: Mattres Pads | C23: =+IF($C$5<$D$2,+'Total Linen March 31st'!#REF!,0) -> #REF! | F23: =+IF($F$5<$D$2,+'Total Linen June 30th'!#REF!,0) -> #REF! | G23: =+F23-C23 -> #REF! | I23: =+IF($I$5<$D$2,+'Total Linen Sept 30th'!#REF!,0) -> #REF! | J23: =+I23-F23 -> #REF! | L23: =+IF($L$5<$D$2,+'Total Linen Dec 31st'!#REF!,0) -> 0 | M23: =+L23-I23 -> #REF!
A24: Blankets | C24: =+IF($C$5<$D$2,+'Total Linen March 31st'!$N$13,0) -> -22.5 | F24: =+IF($F$5<$D$2,+'Total Linen June 30th'!#REF!,0) -> #REF! | G24: =+F24-C24 -> #REF! | I24: =+IF($I$5<$D$2,+'Total Linen Sept 30th'!#REF!,0) -> #REF! | J24: =+I24-F24 -> #REF! | L24: =+IF($L$5<$D$2,+'Total Linen Dec 31st'!#REF!,0) -> 0 | M24: =+L24-I24 -> #REF!
A25: Bed Spreads | C25: =+IF($C$5<$D$2,+'Total Linen March 31st'!$O$13,0) -> 0 | F25: =+IF($F$5<$D$2,+'Total Linen June 30th'!#REF!,0) -> #REF! | G25: =+F25-C25 -> #REF! | I25: =+IF($I$5<$D$2,+'Total Linen Sept 30th'!#REF!,0) -> #REF! | J25: =+I25-F25 -> #REF! | L25: =+IF($L$5<$D$2,+'Total Linen Dec 31st'!#REF!,0) -> 0 | M25: =+L25-I25 -> #REF!
A27: Full / Sofa Sleepers
A28: Flat Sheets | C28: =+IF($C$5<$D$2,+'Total Linen March 31st'!$Q$13,0) -> -22.5 | F28: =+IF($F$5<$D$2,+'Total Linen June 30th'!#REF!,0) -> #REF! | G28: =+F28-C28 -> #REF! | I28: =+IF($I$5<$D$2,+'Total Linen Sept 30th'!#REF!,0) -> #REF! | J28: =+I28-F28 -> #REF! | L28: =+IF($L$5<$D$2,+'Total Linen Dec 31st'!#REF!,0) -> 0 | M28: =+L28-I28 -> #REF!
A29: Fitted Sheets | C29: =+IF($C$5<$D$2,+'Total Linen March 31st'!$S$13,0) -> -22.5 | F29: =+IF($F$5<$D$2,+'Total Linen June 30th'!#REF!,0) -> #REF! | G29: =+F29-C29 -> #REF! | I29: =+IF($I$5<$D$2,+'Total Linen Sept 30th'!#REF!,0) -> #REF! | J29: =+I29-F29 -> #REF! | L29: =+IF($L$5<$D$2,+'Total Linen Dec 31st'!#REF!,0) -> 0 | M29: =+L29-I29 -> #REF!
A30: Extra Pillows | C30: =+IF($C$5<$D$2,+'Total Linen March 31st'!#REF!,0) -> #REF! | F30: =+IF($F$5<$D$2,+'Total Linen June 30th'!#REF!,0) -> #REF! | G30: =+F30-C30 -> #REF! | I30: =+IF($I$5<$D$2,+'Total Linen Sept 30th'!#REF!,0) -> #REF! | J30: =+I30-F30 -> #REF! | L30: =+IF($L$5<$D$2,+'Total Linen Dec 31st'!#REF!,0) -> 0 | M30: =+L30-I30 -> #REF!
A32: Pillows
A33: Firm Pillows | C33: =+IF($C$5<$D$2,+'Total Linen March 31st'!#REF!,0) -> #REF! | F33: =+IF($F$5<$D$2,+'Total Linen June 30th'!#REF!,0) -> #REF! | G33: =+F33-C33 -> #REF! | I33: =+IF($I$5<$D$2,+'Total Linen Sept 30th'!#REF!,0) -> #REF! | J33: =+I33-F33 -> #REF! | L33: =+IF($L$5<$D$2,+'Total Linen Dec 31st'!#REF!,0) -> 0 | M33: =+L33-I33 -> #REF!
A34: Firm Pillow Cases | C34: =+IF($C$5<$D$2,+'Total Linen March 31st'!#REF!,0) -> #REF! | F34: =+IF($F$5<$D$2,+'Total Linen June 30th'!#REF!,0) -> #REF! | G34: =+F34-C34 -> #REF! | I34: =+IF($I$5<$D$2,+'Total Linen Sept 30th'!#REF!,0) -> #REF! | J34: =+I34-F34 -> #REF! | L34: =+IF($L$5<$D$2,+'Total Linen Dec 31st'!#REF!,0) -> 0 | M34: =+L34-I34 -> #REF!
A35: Soft Pillows | C35: =+IF($C$5<$D$2,+'Total Linen March 31st'!$W$13,0) -> 0 | F35: =+IF($F$5<$D$2,+'Total Linen June 30th'!#REF!,0) -> #REF! | G35: =+F35-C35 -> #REF! | I35: =+IF($I$5<$D$2,+'Total Linen Sept 30th'!#REF!,0) -> #REF! | J35: =+I35-F35 -> #REF! | L35: =+IF($L$5<$D$2,+'Total Linen Dec 31st'!#REF!,0) -> 0 | M35: =+L35-I35 -> #REF!
A36: Soft Pillow Cases | C36: =+IF($C$5<$D$2,+'Total Linen March 31st'!X$13,0) -> -22.5 | F36: =+IF($F$5<$D$2,+'Total Linen June 30th'!#REF!,0) -> #REF! | G36: =+F36-C36 -> #REF! | I36: =+IF($I$5<$D$2,+'Total Linen Sept 30th'!#REF!,0) -> #REF! | J36: =+I36-F36 -> #REF! | L36: =+IF($L$5<$D$2,+'Total Linen Dec 31st'!#REF!,0) -> 0 | M36: =+L36-I36 -> #REF!
C38: Quarterly Loss (Qty)
C39: Quarter
C40: 1 | D40: change | F40: 2 | G40: change | I40: 3 | J40: change | L40: 4 | M40: change | N40: Quarterly Average
A41: Terry
A42: Wash Cloths | C42: =+IF($C$5<$D$2,+'Total Linen March 31st'!$B$21,0) -> 0 | F42: =+IF($F$5<$D$2,+'Total Linen June 30th'!$B$11,0) -> 0 | G42: =+F42-C42 -> 0 | I42: =+IF($I$5<$D$2,+'Total Linen Sept 30th'!$B$12,0) -> 0 | J42: =+I42-F42 -> 0 | L42: =+IF($L$5<$D$2,+'Total Linen Dec 31st'!$B$12,0) -> 0 | M42: =+L42-I42 -> 0 | N42: =AVERAGE(C42,F42,I42,L42) -> 0 | P42: This report shows how many of each individual item was lost each quarter. This is a trend report that should help us identify problems and create strategies to minimize our linen loss. The "change" column shows if we lost fewer of that specific item than in the previous quarter. This will be useful if you aggressively target a specific item to reduce the loss levels OR if you have an item that shows a signifiant spike in loss rates. The Quarterly Average column will help show the loss quantity average for the completed quarters to help identify a "normal" loss level. Obviously the goal would be to reduce the average quarterly loss number by progressively reducing the loss each quarter.
A43: Hand Towels | C43: =+IF($C$5<$D$2,+'Total Linen March 31st'!$C$21,0) -> 0 | F43: =+IF($F$5<$D$2,+'Total Linen June 30th'!$C$11,0) -> 0 | G43: =+F43-C43 -> 0 | I43: =+IF($I$5<$D$2,+'Total Linen Sept 30th'!$C$12,0) -> 0 | J43: =+I43-F43 -> 0 | L43: =+IF($L$5<$D$2,+'Total Linen Dec 31st'!$C$12,0) -> 0 | M43: =+L43-I43 -> 0 | N43: =AVERAGE(C43,F43,I43,L43) -> 0
A44: Bath Towels | C44: =+IF($C$5<$D$2,+'Total Linen March 31st'!$D$21,0) -> 0 | F44: =+IF($F$5<$D$2,+'Total Linen June 30th'!$D$11,0) -> 0 | G44: =+F44-C44 -> 0 | I44: =+IF($I$5<$D$2,+'Total Linen Sept 30th'!$D$12,0) -> 0 | J44: =+I44-F44 -> 0 | L44: =+IF($L$5<$D$2,+'Total Linen Dec 31st'!$D$12,0) -> 0 | M44: =+L44-I44 -> 0 | N44: =AVERAGE(C44,F44,I44,L44) -> 0
...
